Workbook

Sheet ENERO
B3: =C32 -> VIGILANT
B4: =C33 -> LAS TERRAZAS DE LA TORRE | Q4: =DATE($C$34,$C$35,1) -> 46023 | Z4: =SUM(AH51+AH62+AH73+AH84+AH95+AH106+AH117+AH128+AH139+AH150+AH161+AH172) -> 1736 | AC4: h. centro
AE5: =IF(CA59=28,IF(CA59="",0,1),IF(CA59=1,IF(CA59="",0,1),"")) | AF5: =IF(CA59=29,IF(CA59="",0,1),IF(CA59=1,IF(CA59="",0,1),"")) | AG5: =IF(CA59=30,IF(CA59="",0,1),IF(CA59=1,IF(CA59="",0,1),"")) | AH5: =IF(CA59=31,IF(CA59="",0,1),IF(CA59=1,IF(CA59="",0,1),"")) -> 1
B6: FESTIVO
B7: DIA SEM. | C7: =IF(AV47="LUNES","lu",IF(AV47="MARTES","ma",IF(AV47="MIERCOLES","mi",IF(AV47="JUEVES","ju",IF(AV47="VIERNES","vi",IF(AV47="SABADO","S",IF(AV47="DOMINGO","D",""))))))) -> ju | D7: =IF(C7="lu","ma",IF(C7="ma","mi",IF(C7="mi","ju",IF(C7="ju","vi",IF(C7="vi","S",IF(C7="S","D",IF(C7="D","lu",""))))))) -> vi | E7: =IF(D7="lu","ma",IF(D7="ma","mi",IF(D7="mi","ju",IF(D7="ju","vi",IF(D7="vi","S",IF(D7="S","D",IF(D7="D","lu",""))))))) -> S | F7: =IF(E7="lu","ma",IF(E7="ma","mi",IF(E7="mi","ju",IF(E7="ju","vi",IF(E7="vi","S",IF(E7="S","D",IF(E7="D","lu",""))))))) -> D | G7: =IF(F7="lu","ma",IF(F7="ma","mi",IF(F7="mi","ju",IF(F7="ju","vi",IF(F7="vi","S",IF(F7="S","D",IF(F7="D","lu",""))))))) -> lu | H7: =IF(G7="lu","ma",IF(G7="ma","mi",IF(G7="mi","ju",IF(G7="ju","vi",IF(G7="vi","S",IF(G7="S","D",IF(G7="D","lu",""))))))) -> ma | I7: =IF(H7="lu","ma",IF(H7="ma","mi",IF(H7="mi","ju",IF(H7="ju","vi",IF(H7="vi","S",IF(H7="S","D",IF(H7="D","lu",""))))))) -> mi | J7: =IF(I7="lu","ma",IF(I7="ma","mi",IF(I7="mi","ju",IF(I7="ju","vi",IF(I7="vi","S",IF(I7="S","D",IF(I7="D","lu",""))))))) -> ju | K7: =IF(J7="lu","ma",IF(J7="ma","mi",IF(J7="mi","ju",IF(J7="ju","vi",IF(J7="vi","S",IF(J7="S","D",IF(J7="D","lu",""))))))) -> vi | ... AD7: =IF(AC7="lu","ma",IF(AC7="ma","mi",IF(AC7="mi","ju",IF(AC7="ju","vi",IF(AC7="vi","S",IF(AC7="S","D",IF(AC7="D","lu",""))))))) -> mi | AE7: =IF(AE8="","",IF(AD7="lu","ma",IF(AD7="ma","mi",IF(AD7="mi","ju",IF(AD7="ju","vi",IF(AD7="vi","S",IF(AD7="S","D",IF(AD7="D","lu","")))))))) -> ju | AF7: =IF(AF8="","",IF(AE7="lu","ma",IF(AE7="ma","mi",IF(AE7="mi","ju",IF(AE7="ju","vi",IF(AE7="vi","S",IF(AE7="S","D",IF(AE7="D","lu","")))))))) -> vi | AG7: =IF(AG8="","",IF(AF7="lu","ma",IF(AF7="ma","mi",IF(AF7="mi","ju",IF(AF7="ju","vi",IF(AF7="vi","S",IF(AF7="S","D",IF(AF7="D","lu","")))))))) -> S
A8: VIGILANTE Nº | C8: 1 | D8: 2 | E8: 3 | F8: 4 | G8: 5 | H8: 6 | I8: 7 | J8: 8 | K8: 9 | L8: 10 | M8: 11 | N8: 12 | O8: 13 | P8: 14 | Q8: 15 | R8: 16 | S8: 17 | T8: 18 | U8: 19 | V8: 20 | W8: 21 | X8: 22 | Y8: 23 | Z8: 24 | AA8: 25 | AB8: 26 | AC8: 27 | AD8: 28 | AE8: =IF(CA59=28,"",IF(CA59=29,29,IF(CA59=30,29,IF(CA59=31,29,"")))) -> 29 | AF8: =IF(CA59=28,"",IF(CA59=29,"",IF(CA59=30,30,IF(CA59=31,30,"")))) -> 30 | AG8: =IF(CA59=28,"",IF(CA59=29,"",IF(CA59=30,"",IF(CA59=31,31,"")))) -> 31 | AH8: HORAS | AI8: EXT | AJ8: FES | AK8: NOC | AL8: DV
A9: JAVI | C9: B | D9: B | E9: B | F9: B | G9: B | H9: B | I9: B | J9: B | K9: B | L9: B | M9: B | N9: B | O9: B | P9: B | Q9: B | R9: B | S9: B | T9: B | U9: B | V9: B | W9: B | X9: B | Y9: B | Z9: B | AA9: B | AB9: B | AC9: B | AD9: B | AE9: B | AF9: B | AG9: B | AH9: =SUM(AH50:AH51) -> 0 | AI9: =AH9-C37 -> -162 | AJ9: =SUM(C55:AG55) -> 0 | AK9: =AK32 -> 0 | AL9: =SUM(C56:AG56) -> 0 | CB9: =ROUNDDOWN(AH9,0) -> 0 | CC9: =AH9-INT(AH9) -> 0 | CD9: =CC9/24 -> 0
A10: PAREDES | C10: N2 | D10: N2 | E10: N2 | F10: N2 | I10: N2 | J10: N2 | N10: N2 | O10: N2 | R10: N2 | S10: N2 | T10: N2 | W10: N2 | X10: N2 | AB10: N2 | AC10: N2 | AF10: N2 | AG10: N2 | AH10: =SUM(AH61:AH62) -> 204 | AI10: =AH10-C37 -> 42 | AJ10: =SUM(C66:AG66) -> 60 | AK10: =AK33 -> 136 | AL10: =SUM(C67:AG67) -> 0
A11: JUAN | C11: N1 | I11: D2 | J11: D2 | K11: D2 | L11: D2 | M11: D2 | N11: D2 | O11: D2 | R11: D2 | S11: D2 | T11: D2 | W11: D2 | X11: D2 | AB11: D2 | AC11: D2 | AF11: D2 | AG11: D2 | AH11: =SUM(AH72:AH73) -> 204 | AI11: =AH11-C37 -> 42 | AJ11: =SUM(C77:AG77) -> 60 | AK11: =AK34 -> 8 | AL11: =SUM(C78:AG78) -> 0
A12: MILOU | D12: D2 | E12: D2 | F12: D2 | G12: D2 | H12: D2 | I12: D1 | J12: D1 | P12: D2 | Q12: D2 | U12: D2 | V12: D2 | Y12: D2 | Z12: D2 | AA12: D2 | AD12: D2 | AE12: D2 | AH12: =SUM(AH83:AH84) -> 192 | AI12: =AH12-C37 -> 30 | AJ12: =SUM(C88:AG88) -> 48 | AK12: =AK35 -> 0 | AL12: =SUM(C89:AG89) -> 0
A13: CAUTO | C13: D2 | D13: D1 | E13: D1 | F13: D1 | G13: N2 | H13: N2 | L13: L | M13: L | N13: L | O13: L | P13: L | Q13: L | R13: L | S13: L | T13: L | U13: L | V13: L | W13: D1 | X13: D1 | Y13: D1 | Z13: D1 | AA13: D1 | AB13: D1 | AC13: D1 | AF13: D1 | AG13: D1 | AH13: =SUM(AH94:AH95) -> 180 | AI13: =AH13-C37 -> 18 | AJ13: =SUM(C99:AG99) -> 60 | AK13: =AK36 -> 16 | AL13: =SUM(C100:AG100) -> 0
A14: HIDALGO | C14: D1 | G14: D1 | H14: D1 | K14: N1 | L14: N1 | M14: N1 | P14: D1 | Q14: D1 | U14: D1 | V14: D1 | Y14: D1 | Z14: D1 | AA14: D1 | AD14: D1 | AE14: D1 | AH14: =SUM(AH105:AH106) -> 180 | AI14: =AH14-C37 -> 18 | AJ14: =SUM(C110:AG110) -> 48 | AK14: =AK37 -> 24 | AL14: =SUM(C111:AG111) -> 0
A15: SAMUEL | D15: N1 | E15: N1 | F15: N1 | G15: L | H15: L | I15: N1 | J15: N1 | K15: L | L15: L | M15: L | O15: N1 | Q15: N3 | R15: N1 | S15: N1 | T15: N1 | U15: N3 | X15: N1 | Y15: L | Z15: L | AA15: L | AB15: N1 | AC15: N1 | AF15: N1 | AG15: N1 | AH15: =SUM(AH116:AH117) -> 184 | AI15: =AH15-C37 -> 22 | AJ15: =SUM(C121:AG121) -> 60 | AK15: =AK38 -> 128 | AL15: =SUM(C122:AG122) -> 0
A16: PAREJO | C16: L | D16: L | E16: L | F16: L | G16: L | H16: L | K16: N1 | L16: N1 | M16: N1 | N16: N1 | P16: N2 | Q16: N2 | U16: N2 | V16: N2 | W16: N1 | Y16: N1 | Z16: N1 | AA16: N1 | AD16: N2 | AE16: N2 | AH16: =SUM(AH127:AH128) -> 168 | AI16: =AH16-C37 -> 6 | AJ16: =SUM(C132:AG132) -> 48 | AK16: =AK39 -> 112 | AL16: =SUM(C133:AG133) -> 0
A17: PEDREÑO | G17: N3 | H17: N3 | K17: N3 | L17: N3 | M17: N3 | Q17: N1 | Y17: N3 | Z17: N3 | AA17: N3 | AH17: =SUM(AH138:AH139) -> 76 | AI17: =AH17-C37 -> -86 | AJ17: =SUM(C143:AG143) -> 32 | AK17: =AK40 -> 72 | AL17: =SUM(C144:AG144) -> 0
A18: ENRIQUE | G18: N1 | H18: N1 | K18: D1 | L18: D1 | M18: D1 | N18: D1 | O18: D1 | P18: N1 | R18: D1 | S18: D1 | T18: D1 | U18: N1 | V18: N1 | AD18: N1 | AE18: N1 | AH18: =SUM(AH149:AH150) -> 180 | AI18: =AH18-C37 -> 18 | AJ18: =SUM(C154:AG154) -> 48 | AK18: =AK41 -> 56 | AL18: =SUM(C155:AG155) -> 0
A19: MIGUEL | C19: N3 | D19: N3 | E19: N3 | F19: N3 | I19: N3 | J19: N3 | N19: N3 | O19: N3 | P19: N3 | R19: N3 | S19: N3 | T19: N3 | V19: N3 | W19: N3 | X19: N3 | AB19: N3 | AC19: N3 | AD19: N3 | AE19: N3 | AF19: N3 | AG19: N3 | AH19: =SUM(AH160:AH161) -> 168 | AI19: =AH19-C37 -> 6 | AJ19: =SUM(C165:AG165) -> 40 | AK19: =AK42 -> 168 | AL19: =SUM(C166:AG166) -> 0
AH20: =SUM(AH171:AH172) -> 0 | AI20: =AH20-C37 -> -162 | AJ20: =SUM(C176:AG176) -> 0 | AK20: =AK43 -> 0 | AL20: =SUM(C177:AG177) -> 0
B21: SUMAS | C21: =SUM(C51+C62+C73+C84+C95+C106+C117+C128+C139+C150+C161+C172) -> 56 | D21: =SUM(D51+D62+D73+D84+D95+D106+D117+D128+D139+D150+D161+D172) -> 56 | E21: =SUM(E51+E62+E73+E84+E95+E106+E117+E128+E139+E150+E161+E172) -> 56 | F21: =SUM(F51+F62+F73+F84+F95+F106+F117+F128+F139+F150+F161+F172) -> 56 | G21: =SUM(G51+G62+G73+G84+G95+G106+G117+G128+G139+G150+G161+G172) -> 56 | H21: =SUM(H51+H62+H73+H84+H95+H106+H117+H128+H139+H150+H161+H172) -> 56 | I21: =SUM(I51+I62+I73+I84+I95+I106+I117+I128+I139+I150+I161+I172) -> 56 | J21: =SUM(J51+J62+J73+J84+J95+J106+J117+J128+J139+J150+J161+J172) -> 56 | ... AG21: =SUM(AG51+AG62+AG73+AG84+AG95+AG106+AG117+AG128+AG139+AG150+AG161+AG172) -> 56
C23: TURNOS | J23: TURNOS | Q23: JORNADA PARTIDA | AQ23: 5 < 10 el 5 es menor que 10
C24: =R32 -> D1 | D24: =S32 -> 0.25 | F24: A | G24: =V32 -> 0.75 | J24: =R35 -> N2 | K24: =S35 -> 0.79166667 | M24: A | N24: =V35 -> 0.29166667 | Q24: =R38 -> G | T24: A | Y24: A | AG24: X | AH24: FESTIVO | AQ24: 10 > 3 el 10 es mayor que 3
C25: =R33 -> N1 | D25: =S33 -> 0.75 | F25: A | G25: =V33 -> 0.25 | J25: =R36 -> N3 | K25: =S36 -> 0.91666667 | M25: A | N25: =V36 -> 0.25 | Q25: =R39 -> H | T25: A | Y25: A | AG25: V | AH25: VACACIONES | AQ25: 1 > 0 1 es mayor que cero
C26: =R34 -> D2 | D26: =S34 -> 0.29166667 | F26: A | G26: =V34 -> 0.79166667 | J26: =R37 -> F | K26: =S37 -> 0.20833333 | M26: A | N26: =V37 -> 0.25 | Q26: =R40 -> I | T26: A | Y26: A | AG26: PR | AH26: P. RETRIBUIDO | AQ26: -5 < 0 negativo 5 es menor que cero
B29: NOTAS: | C29: =E43 -> *Aquí notas que se vean en el cuadrante...
AN30: AN | AP30: AP | AQ30: AQ | AX30: AX | AZ30: AZ | BD30: b
A31: CONFIGURACION CUADRANTE | R31: TURNOS | AD31: CALCULAR MINUTOS | AK31: NOC | AN31: NOCTUR. | AO31: T. HORAS | AP31: ENTRADA | AQ31: SALIDA | AR31: CONDICIONES DE NOCTURNIDAD | BA31: SUMA HR. | BB31: CALCULO HORAS | BD31: NOCTURNIDAD
A32: EMPRESA | C32: VIGILANT | R32: D1 | S32: 0.25 | U32: A | V32: 0.75 | AD32: MINUTOS | AH32: 0.5 | AI32: =AH32/24 -> 0.020833333 | AK32: =AH49 -> 0 | AL32: V1 | AN32: =IF(AS32/24=0,0,AS32/24) -> 0 | AO32: =IF(BA32=0,"",BA32) -> 0.5 | AP32: =S32*24 -> 6 | AQ32: =V32*24 -> 18 | AR32: =AS32 -> 0 | AS32: =IF(AV32>=4,AT32,AT32) -> 0 | AT32: =IF(AV32>8,8,AU32) -> 0 | AU32: =IF(AV32<0,0,AV32) -> 0 | AV32: =IF(AP32=AQ32,0,IF(AP32>AQ32,AW32,IF(AP32>=6,AX32,AQ32-AP32))) -> -12 | AW32: =IF(AP32<6,(AQ32-22+24)+(6-AP32),IF(AP32>=22,AY32,IF(AV2<=6,(AQ32-22)+24,8))) -> 20 | AX32: =IF(AQ32>22,AZ32,IF(AP32<AQ32,AP32-AQ32,IF(AP32>6,0,(6-AP32)))) -> -12 | AY32: =IF(AQ32<=6,(AQ32-AP32)+24,IF(AQ32>22,8,(6-AP32)+24)) -> 24 | AZ32: =IF(AP32<=6,(6-AP32)+(AQ32-22),IF(AP32>22,(AQ32-AP32),(AQ32-22))) -> -4 | BA32: =IF(V32-S32>=0,V32-S32,V32-S32+24) -> 0.5 | BB32: =IF(AO32<1,AO32*24,(AO32-24)*24) -> 12 | BC32: =IF(BB32>=0,BB32,BB32+24) -> 12 | BD32: =IF(AX32<=0,AN32,IF(AX32>=0.1,AX32/24)) -> 0 | BE32: =IF(BD38>=4,IF(BD38="",0,8),IF(BD38>=0.1,IF(BD38="",0,BD38),""))
A33: CENTRO | C33: LAS TERRAZAS DE LA TORRE | R33: N1 | S33: 0.75 | U33: A | V33: 0.25 | AK33: =AH60 -> 136 | AL33: V2 | AN33: =IF(AS33/24=0,0,AS33/24) -> 0.33333333 | AO33: =IF(BA33=0,"",BA33) -> 23.5 | AP33: =S33*24 -> 18 | AQ33: =V33*24 -> 6 | AR33: =AS33 -> 8 | AS33: =IF(AV33>=4,AT33,AT33) -> 8 | AT33: =IF(AV33>8,8,AU33) -> 8 | AU33: =IF(AV33<0,0,AV33) -> 8 | AV33: =IF(AP33=AQ33,0,IF(AP33>AQ33,AW33,IF(AP33>=6,AX33,AQ33-AP33))) -> 8 | AW33: =IF(AP33<6,(AQ33-22+24)+(6-AP33),IF(AP33>=22,AY33,IF(AV3<=6,(AQ33-22)+24,8))) -> 8 | AX33: =IF(AQ33>22,AZ33,IF(AP33<AQ33,AP33-AQ33,IF(AP33>6,0,(6-AP33)))) -> 0 | AY33: =IF(AQ33<=6,(AQ33-AP33)+24,IF(AQ33>22,8,(6-AP33)+24)) -> 12 | AZ33: =IF(AP33<=6,(6-AP33)+(AQ33-22),IF(AP33>22,(AQ33-AP33),(AQ33-22))) -> -16 | BA33: =IF(V33-S33>=0,V33-S33,V33-S33+24) -> 23.5 | BB33: =IF(AO33<1,AO33*24,(AO33-24)*24) -> -12 | BC33: =IF(BB33>=0,BB33,BB33+24) -> 12 | BD33: =IF(AX33<=0,AN33,IF(AX33>=0.1,AX33/24)) -> 0.33333333 | BE33: =IF(BD39>=4,IF(BD39="",0,8),IF(BD39>=0.1,IF(BD39="",0,BD39),""))
A34: AÑO | C34: 2026 | R34: D2 | S34: 0.29166667 | U34: A | V34: 0.79166667 | AK34: =AH71 -> 8 | AL34: V3 | AN34: =IF(AS34/24=0,0,AS34/24) -> 0 | AO34: =IF(BA34=0,"",BA34) -> 0.5 | AP34: =S34*24 -> 7 | AQ34: =V34*24 -> 19 | AR34: =AS34 -> 0 | AS34: =IF(AV34>=4,AT34,AT34) -> 0 | AT34: =IF(AV34>8,8,AU34) -> 0 | AU34: =IF(AV34<0,0,AV34) -> 0 | AV34: =IF(AP34=AQ34,0,IF(AP34>AQ34,AW34,IF(AP34>=6,AX34,AQ34-AP34))) -> -12 | AW34: =IF(AP34<6,(AQ34-22+24)+(6-AP34),IF(AP34>=22,AY34,IF(AV4<=6,(AQ34-22)+24,8))) -> 21 | AX34: =IF(AQ34>22,AZ34,IF(AP34<AQ34,AP34-AQ34,IF(AP34>6,0,(6-AP34)))) -> -12 | AY34: =IF(AQ34<=6,(AQ34-AP34)+24,IF(AQ34>22,8,(6-AP34)+24)) -> 23 | AZ34: =IF(AP34<=6,(6-AP34)+(AQ34-22),IF(AP34>22,(AQ34-AP34),(AQ34-22))) -> -3 | BA34: =IF(V34-S34>=0,V34-S34,V34-S34+24) -> 0.5 | BB34: =IF(AO34<1,AO34*24,(AO34-24)*24) -> 12 | BC34: =IF(BB34>=0,BB34,BB34+24) -> 12 | BD34: =IF(AX34<=0,AN34,IF(AX34>=0.1,AX34/24)) -> 0 | BE34: =IF(BD40>=4,IF(BD40="",0,8),IF(BD40>=0.1,IF(BD40="",0,BD40),""))
A35: MES | C35: 1 | R35: N2 | S35: 0.79166667 | U35: A | V35: 0.29166667 | AK35: =AH82 -> 0 | AL35: V4 | AN35: =IF(AS35/24=0,0,AS35/24) -> 0.33333333 | AO35: =IF(BA35=0,"",BA35) -> 23.5 | AP35: =S35*24 -> 19 | AQ35: =V35*24 -> 7 | AR35: =AS35 -> 8 | AS35: =IF(AV35>=4,AT35,AT35) -> 8 | AT35: =IF(AV35>8,8,AU35) -> 8 | AU35: =IF(AV35<0,0,AV35) -> 9 | AV35: =IF(AP35=AQ35,0,IF(AP35>AQ35,AW35,IF(AP35>=6,AX35,AQ35-AP35))) -> 9 | AW35: =IF(AP35<6,(AQ35-22+24)+(6-AP35),IF(AP35>=22,AY35,IF(AV5<=6,(AQ35-22)+24,8))) -> 9 | AX35: =IF(AQ35>22,AZ35,IF(AP35<AQ35,AP35-AQ35,IF(AP35>6,0,(6-AP35)))) -> 0 | AY35: =IF(AQ35<=6,(AQ35-AP35)+24,IF(AQ35>22,8,(6-AP35)+24)) -> 11 | AZ35: =IF(AP35<=6,(6-AP35)+(AQ35-22),IF(AP35>22,(AQ35-AP35),(AQ35-22))) -> -15 | BA35: =IF(V35-S35>=0,V35-S35,V35-S35+24) -> 23.5 | BB35: =IF(AO35<1,AO35*24,(AO35-24)*24) -> -12 | BC35: =IF(BB35>=0,BB35,BB35+24) -> 12 | BD35: =IF(AX35<=0,AN35,IF(AX35>=0.1,AX35/24)) -> 0.33333333
A36: VACACIONES | C36: 5.22 | R36: N3 | S36: 0.91666667 | U36: A | V36: 0.25 | AK36: =AH93 -> 16 | AL36: V5 | AN36: =IF(AS36/24=0,0,AS36/24) -> 0.33333333 | AO36: =IF(BA36=0,"",BA36) -> 23.333333 | AP36: =S36*24 -> 22 | AQ36: =V36*24 -> 6 | AR36: =AS36 -> 8 | AS36: =IF(AV36>=4,AT36,AT36) -> 8 | AT36: =IF(AV36>8,8,AU36) -> 8 | AU36: =IF(AV36<0,0,AV36) -> 8 | AV36: =IF(AP36=AQ36,0,IF(AP36>AQ36,AW36,IF(AP36>=6,AX36,AQ36-AP36))) -> 8 | AW36: =IF(AP36<6,(AQ36-22+24)+(6-AP36),IF(AP36>=22,AY36,IF(AV6<=6,(AQ36-22)+24,8))) -> 8 | AX36: =IF(AQ36>22,AZ36,IF(AP36<AQ36,AP36-AQ36,IF(AP36>6,0,(6-AP36)))) -> 0 | AY36: =IF(AQ36<=6,(AQ36-AP36)+24,IF(AQ36>22,8,(6-AP36)+24)) -> 8 | AZ36: =IF(AP36<=6,(6-AP36)+(AQ36-22),IF(AP36>22,(AQ36-AP36),(AQ36-22))) -> -16 | BA36: =IF(V36-S36>=0,V36-S36,V36-S36+24) -> 23.333333 | BB36: =IF(AO36<1,AO36*24,(AO36-24)*24) -> -16 | BC36: =IF(BB36>=0,BB36,BB36+24) -> 8 | BD36: =IF(AX36<=0,AN36,IF(AX36>=0.1,AX36/24)) -> 0.33333333
A37: JORNADA | C37: 162 | R37: =CONTROL!F40 -> F | S37: =CONTROL!G40 -> 0.20833333 | U37: A | V37: =CONTROL!H40 -> 0.25 | AK37: =AH104 -> 24 | AL37: V6 | AN37: =IF(AS37/24=0,0,AS37/24) -> 0.041666667 | AO37: =IF(BA37=0,"",BA37) -> 0.041666667 | AP37: =S37*24 -> 5 | AQ37: =V37*24 -> 6 | AR37: =AS37 -> 1 | AS37: =IF(AV37>=4,AT37,AT37) -> 1 | AT37: =IF(AV37>8,8,AU37) -> 1 | AU37: =IF(AV37<0,0,AV37) -> 1 | AV37: =IF(AP37=AQ37,0,IF(AP37>AQ37,AW37,IF(AP37>=6,AX37,AQ37-AP37))) -> 1 | AW37: =IF(AP37<6,(AQ37-22+24)+(6-AP37),IF(AP37>=22,AY37,IF(AV7<=6,(AQ37-22)+24,8))) -> 9 | AX37: =IF(AQ37>22,AZ37,IF(AP37<AQ37,AP37-AQ37,IF(AP37>6,0,(6-AP37)))) -> -1 | AY37: =IF(AQ37<=6,(AQ37-AP37)+24,IF(AQ37>22,8,(6-AP37)+24)) -> 25 | AZ37: =IF(AP37<=6,(6-AP37)+(AQ37-22),IF(AP37>22,(AQ37-AP37),(AQ37-22))) -> -15 | BA37: =IF(V37-S37>=0,V37-S37,V37-S37+24) -> 0.041666667 | BB37: =IF(AO37<1,AO37*24,(AO37-24)*24) -> 1 | BC37: =IF(BB37>=0,BB37,BB37+24) -> 1 | BD37: =IF(AX37<=0,AN37,IF(AX37>=0.1,AX37/24)) -> 0.041666667
A38: P. RETRIBUIDO | C38: 0 | R38: =CONTROL!F41 -> G | S38: =CONTROL!G41 -> 0.29166667 | U38: A | V38: =CONTROL!H41 -> 0.33333333 | AK38: =AH115 -> 128 | AL38: V7 | AN38: =IF(AS38/24=0,0,AS38/24) -> 0 | AO38: =IF(BA38=0,"",BA38) -> 0.041666667 | AP38: =S38*24 -> 7 | AQ38: =V38*24 -> 8 | AR38: =AS38 -> 0 | AS38: =IF(AV38>=4,AT38,AT38) -> 0 | AT38: =IF(AV38>8,8,AU38) -> 0 | AU38: =IF(AV38<0,0,AV38) -> 0 | AV38: =IF(AP38=AQ38,0,IF(AP38>AQ38,AW38,IF(AP38>=6,AX38,AQ38-AP38))) -> -1 | AW38: =IF(AP38<6,(AQ38-22+24)+(6-AP38),IF(AP38>=22,AY38,IF(AV8<=6,(AQ38-22)+24,8))) -> 10 | AX38: =IF(AQ38>22,AZ38,IF(AP38<AQ38,AP38-AQ38,IF(AP38>6,0,(6-AP38)))) -> -1 | AY38: =IF(AQ38<=6,(AQ38-AP38)+24,IF(AQ38>22,8,(6-AP38)+24)) -> 23 | AZ38: =IF(AP38<=6,(6-AP38)+(AQ38-22),IF(AP38>22,(AQ38-AP38),(AQ38-22))) -> -14 | BA38: =IF(V38-S38>=0,V38-S38,V38-S38+24) -> 0.041666667 | BB38: =IF(AO38<1,AO38*24,(AO38-24)*24) -> 1 | BC38: =IF(BB38>=0,BB38,BB38+24) -> 1 | BD38: =IF(AX38<=0,AN38,IF(AX38>=0.1,AX38/24)) -> 0
R39: =CONTROL!F42 -> H | S39: =CONTROL!G42 -> 0.33333333 | U39: A | V39: =CONTROL!H42 -> 0.375 | AK39: =AH126 -> 112 | AL39: V8 | AN39: =IF(AS39/24=0,0,AS39/24) -> 0 | AO39: =IF(BA39=0,"",BA39) -> 0.041666667 | AP39: =S39*24 -> 8 | AQ39: =V39*24 -> 9 | AR39: =AS39 -> 0 | AS39: =IF(AV39>=4,AT39,AT39) -> 0 | AT39: =IF(AV39>8,8,AU39) -> 0 | AU39: =IF(AV39<0,0,AV39) -> 0 | AV39: =IF(AP39=AQ39,0,IF(AP39>AQ39,AW39,IF(AP39>=6,AX39,AQ39-AP39))) -> -1 | AW39: =IF(AP39<6,(AQ39-22+24)+(6-AP39),IF(AP39>=22,AY39,IF(AV9<=6,(AQ39-22)+24,8))) -> 11 | AX39: =IF(AQ39>22,AZ39,IF(AP39<AQ39,AP39-AQ39,IF(AP39>6,0,(6-AP39)))) -> -1 | AY39: =IF(AQ39<=6,(AQ39-AP39)+24,IF(AQ39>22,8,(6-AP39)+24)) -> 22 | AZ39: =IF(AP39<=6,(6-AP39)+(AQ39-22),IF(AP39>22,(AQ39-AP39),(AQ39-22))) -> -13 | BA39: =IF(V39-S39>=0,V39-S39,V39-S39+24) -> 0.041666667 | BB39: =IF(AO39<1,AO39*24,(AO39-24)*24) -> 1 | BC39: =IF(BB39>=0,BB39,BB39+24) -> 1 | BD39: =IF(AX39<=0,AN39,IF(AX39>=0.1,AX39/24)) -> 0
R40: =CONTROL!F43 -> I | S40: =CONTROL!G43 -> 0.41666667 | U40: A | V40: =CONTROL!H43 -> 0.45833333 | AK40: =AH137 -> 72 | AL40: V9 | AN40: =IF(AS40/24=0,0,AS40/24) -> 0 | AO40: =IF(BA40=0,"",BA40) -> 0.041666667 | AP40: =S40*24+24 -> 34 | AQ40: =V40*24 -> 11 | AR40: =AS40 -> 0 | AS40: =IF(AV40>=4,AT40,AT40) -> 0 | AT40: =IF(AV40>8,8,AU40) -> 0 | AU40: =IF(AV40<0,0,AV40) -> 0 | AV40: =IF(AP40=AQ40,0,IF(AP40>AQ40,AW40,IF(AP40>=6,AX40,AQ40-AP40))) -> -4 | AW40: =IF(AP40<6,(AQ40-22+24)+(6-AP40),IF(AP40>=22,AY40,IF(AV10<=6,(AQ40-22)+24,8))) -> -4 | AX40: =IF(AQ40>22,AZ40,IF(AP40<AQ40,AP40-AQ40,IF(AP40>6,0,(6-AP40)))) -> 0 | AY40: =IF(AQ40<=6,(AQ40-AP40)+24,IF(AQ40>22,8,(6-AP40)+24)) -> -4 | AZ40: =IF(AP40<=6,(6-AP40)+(AQ40-22),IF(AP40>22,(AQ40-AP40),(AQ40-22))) -> -23 | BA40: =IF(V40-S40>=0,V40-S40,V40-S40+24) -> 0.041666667 | BB40: =IF(AO40<1,AO40*24,(AO40-24)*24) -> 1 | BC40: =IF(BB40>=0,BB40,BB40+24) -> 1 | BD40: =IF(AX40<=0,AN40,IF(AX40>=0.1,AX40/24)) -> 0
AK41: =AH148 -> 56 | AL41: V10 | AP41: =S41*24 -> 0 | AR41: 1 | AS41: 2 | AT41: 3 | AU41: 4 | AV41: 5 | AW41: 6 | AX41: 7 | AY41: 8 | AZ41: 9
C42: http://oscar.org.es | W42: =CONTROL!B38 -> OSCAR ORGEIRA © 20.03.00 EXCEL | AK42: =AH159 -> 168 | AL42: V11
C43: notas | E43: *Aquí notas que se vean en el cuadrante... | AK43: =AH170 -> 0 | AL43: V12
BE44: =INDEX({"do";"lu";"ma";"mi";"ju";"vi";"sa"},1+MOD($AR$47+4-2,7)) -> ju
B45: FEST. FINDE | C45: =IF(C7="S",IF(C7="",0,1),IF(C7="D",IF(C7="",0,1),"")) | D45: =IF(D7="S",IF(D7="",0,1),IF(D7="D",IF(D7="",0,1),"")) | E45: =IF(E7="S",IF(E7="",0,1),IF(E7="D",IF(E7="",0,1),"")) -> 1 | F45: =IF(F7="S",IF(F7="",0,1),IF(F7="D",IF(F7="",0,1),"")) -> 1 | G45: =IF(G7="S",IF(G7="",0,1),IF(G7="D",IF(G7="",0,1),"")) | H45: =IF(H7="S",IF(H7="",0,1),IF(H7="D",IF(H7="",0,1),"")) | I45: =IF(I7="S",IF(I7="",0,1),IF(I7="D",IF(I7="",0,1),"")) | J45: =IF(J7="S",IF(J7="",0,1),IF(J7="D",IF(J7="",0,1),"")) | ... AH45: =IF(AH7="S",IF(AH7="",0,1),IF(AH7="D",IF(AH7="",0,1),"")) | AI45: SUMAS | BE45: =IF(MONTH($Q$4)<>MONTH($Q$4-(WEEKDAY($Q$4,1)-($AR$47-1))-IF((WEEKDAY($Q$4,1)-($AR$47-1))<=0,7,0)+(ROW(BE45)-ROW($AN$51))*7+(COLUMN(BE45)-COLUMN($AN$51)+1)),"",$Q$4-(WEEKDAY($Q$4,1)-($AR$47-1))-IF((WEEKDAY($Q$4,1)-($AR$47-1))<=0,7,0)+(ROW(BE45)-ROW($AN$51))*7+(COLUMN(BE45)-COLUMN($AN$51)+1))
...

Sheet FEBRERO
B3: =C32 -> EMPRESA
B4: =C33 -> CENTRO | Q4: =DATE($C$34,$C$35,1) -> 46054 | Z4: =SUM(AH51+AH62+AH73+AH84+AH95+AH106+AH117+AH128+AH139+AH150+AH161+AH172) -> 1008 | AC4: h. centro
AE5: =IF(CA59=28,IF(CA59="",0,1),IF(CA59=1,IF(CA59="",0,1),"")) -> 1 | AF5: =IF(CA59=29,IF(CA59="",0,1),IF(CA59=1,IF(CA59="",0,1),"")) | AG5: =IF(CA59=30,IF(CA59="",0,1),IF(CA59=1,IF(CA59="",0,1),"")) | AH5: =IF(CA59=31,IF(CA59="",0,1),IF(CA59=1,IF(CA59="",0,1),""))
B6: FESTIVO
B7: DIA SEM. | C7: =IF(AV47="LUNES","lu",IF(AV47="MARTES","ma",IF(AV47="MIERCOLES","mi",IF(AV47="JUEVES","ju",IF(AV47="VIERNES","vi",IF(AV47="SABADO","S",IF(AV47="DOMINGO","D",""))))))) -> D | D7: =IF(C7="lu","ma",IF(C7="ma","mi",IF(C7="mi","ju",IF(C7="ju","vi",IF(C7="vi","S",IF(C7="S","D",IF(C7="D","lu",""))))))) -> lu | E7: =IF(D7="lu","ma",IF(D7="ma","mi",IF(D7="mi","ju",IF(D7="ju","vi",IF(D7="vi","S",IF(D7="S","D",IF(D7="D","lu",""))))))) -> ma | F7: =IF(E7="lu","ma",IF(E7="ma","mi",IF(E7="mi","ju",IF(E7="ju","vi",IF(E7="vi","S",IF(E7="S","D",IF(E7="D","lu",""))))))) -> mi | G7: =IF(F7="lu","ma",IF(F7="ma","mi",IF(F7="mi","ju",IF(F7="ju","vi",IF(F7="vi","S",IF(F7="S","D",IF(F7="D","lu",""))))))) -> ju | H7: =IF(G7="lu","ma",IF(G7="ma","mi",IF(G7="mi","ju",IF(G7="ju","vi",IF(G7="vi","S",IF(G7="S","D",IF(G7="D","lu",""))))))) -> vi | I7: =IF(H7="lu","ma",IF(H7="ma","mi",IF(H7="mi","ju",IF(H7="ju","vi",IF(H7="vi","S",IF(H7="S","D",IF(H7="D","lu",""))))))) -> S | J7: =IF(I7="lu","ma",IF(I7="ma","mi",IF(I7="mi","ju",IF(I7="ju","vi",IF(I7="vi","S",IF(I7="S","D",IF(I7="D","lu",""))))))) -> D | K7: =IF(J7="lu","ma",IF(J7="ma","mi",IF(J7="mi","ju",IF(J7="ju","vi",IF(J7="vi","S",IF(J7="S","D",IF(J7="D","lu",""))))))) -> lu | ... AD7: =IF(AC7="lu","ma",IF(AC7="ma","mi",IF(AC7="mi","ju",IF(AC7="ju","vi",IF(AC7="vi","S",IF(AC7="S","D",IF(AC7="D","lu",""))))))) -> S | AE7: =IF(AE8="","",IF(AD7="lu","ma",IF(AD7="ma","mi",IF(AD7="mi","ju",IF(AD7="ju","vi",IF(AD7="vi","S",IF(AD7="S","D",IF(AD7="D","lu","")))))))) | AF7: =IF(AF8="","",IF(AE7="lu","ma",IF(AE7="ma","mi",IF(AE7="mi","ju",IF(AE7="ju","vi",IF(AE7="vi","S",IF(AE7="S","D",IF(AE7="D","lu","")))))))) | AG7: =IF(AG8="","",IF(AF7="lu","ma",IF(AF7="ma","mi",IF(AF7="mi","ju",IF(AF7="ju","vi",IF(AF7="vi","S",IF(AF7="S","D",IF(AF7="D","lu",""))))))))
A8: VIGILANTE Nº | C8: 1 | D8: 2 | E8: 3 | F8: 4 | G8: 5 | H8: 6 | I8: 7 | J8: 8 | K8: 9 | L8: 10 | M8: 11 | N8: 12 | O8: 13 | P8: 14 | Q8: 15 | R8: 16 | S8: 17 | T8: 18 | U8: 19 | V8: 20 | W8: 21 | X8: 22 | Y8: 23 | Z8: 24 | AA8: 25 | AB8: 26 | AC8: 27 | AD8: 28 | AE8: =IF(CA59=28,"",IF(CA59=29,29,IF(CA59=30,29,IF(CA59=31,29,"")))) | AF8: =IF(CA59=28,"",IF(CA59=29,"",IF(CA59=30,30,IF(CA59=31,30,"")))) | AG8: =IF(CA59=28,"",IF(CA59=29,"",IF(CA59=30,"",IF(CA59=31,31,"")))) | AH8: HORAS | AI8: EXT | AJ8: FES | AK8: NOC | AL8: DV
A9: JAVI | C9: N1 | G9: N2 | H9: N2 | I9: N2 | J9: N2 | M9: N2 | N9: N2 | R9: N2 | S9: N2 | V9: N2 | W9: N2 | X9: N2 | AA9: N2 | AB9: N2 | AH9: =SUM(AH50:AH51) -> 168 | AI9: =AH9-C37 -> 6 | AJ9: =SUM(C55:AG55) -> 54 | AK9: =AK32 -> 112 | AL9: =SUM(C56:AG56) -> 0 | CB9: =ROUNDDOWN(AH9,0) -> 168 | CC9: =AH9-INT(AH9) -> 0 | CD9: =CC9/24 -> 0
A10: PAREDES | D10: N2 | E10: N2 | F10: N2 | K10: N2 | L10: N2 | O10: N2 | P10: N2 | Q10: N2 | T10: N2 | U10: N2 | Y10: N2 | Z10: N2 | AC10: N2 | AD10: N2 | AH10: =SUM(AH61:AH62) -> 168 | AI10: =AH10-C37 -> 6 | AJ10: =SUM(C66:AG66) -> 36 | AK10: =AK33 -> 112 | AL10: =SUM(C67:AG67) -> 0
A11: JUAN | C11: B | D11: B | E11: B | F11: B | G11: B | H11: B | I11: B | J11: B | K11: B | L11: B | M11: B | N11: B | O11: B | P11: B | Q11: B | R11: B | S11: B | T11: B | U11: B | V11: B | W11: B | X11: B | Y11: B | Z11: B | AA11: B | AB11: B | AC11: B | AD11: B | AH11: =SUM(AH72:AH73) -> 0 | AI11: =AH11-C37 -> -162 | AJ11: =SUM(C77:AG77) -> 0 | AK11: =AK34 -> 0 | AL11: =SUM(C78:AG78) -> 0
A12: MILOU | D12: D2 | E12: D2 | H12: D2 | I12: D2 | J12: D2 | M12: D2 | N12: D2 | R12: D2 | S12: D2 | V12: D2 | W12: D2 | X12: D2 | AA12: D2 | AB12: D2 | AH12: =SUM(AH83:AH84) -> 168 | AI12: =AH12-C37 -> 6 | AJ12: =SUM(C88:AG88) -> 48 | AK12: =AK35 -> 0 | AL12: =SUM(C89:AG89) -> 0
A13: X | AH13: =SUM(AH94:AH95) -> 0 | AI13: =AH13-C37 -> -162 | AJ13: =SUM(C99:AG99) -> 0 | AK13: =AK36 -> 0 | AL13: =SUM(C100:AG100) -> 0
A14: HIDALGO | D14: D1 | E14: D1 | H14: D1 | I14: D1 | J14: D1 | M14: D1 | N14: D1 | R14: D1 | S14: D1 | V14: D1 | W14: D1 | X14: D1 | AA14: D1 | AB14: D1 | AH14: =SUM(AH105:AH106) -> 168 | AI14: =AH14-C37 -> 6 | AJ14: =SUM(C110:AG110) -> 48 | AK14: =AK37 -> 0 | AL14: =SUM(C111:AG111) -> 0
A15: SAMUEL | C15: D2 | F15: D2 | G15: D2 | K15: D2 | L15: D2 | O15: D2 | P15: D2 | Q15: D2 | T15: D2 | U15: D2 | Y15: D2 | Z15: D2 | AC15: D2 | AD15: D2 | AH15: =SUM(AH116:AH117) -> 168 | AI15: =AH15-C37 -> 6 | AJ15: =SUM(C121:AG121) -> 48 | AK15: =AK38 -> 0 | AL15: =SUM(C122:AG122) -> 0
A16: PAREJO | AH16: =SUM(AH127:AH128) -> 0 | AI16: =AH16-C37 -> -162 | AJ16: =SUM(C132:AG132) -> 0 | AK16: =AK39 -> 0 | AL16: =SUM(C133:AG133) -> 0
A17: PEDREÑO | AH17: =SUM(AH138:AH139) -> 0 | AI17: =AH17-C37 -> -162 | AJ17: =SUM(C143:AG143) -> 0 | AK17: =AK40 -> 0 | AL17: =SUM(C144:AG144) -> 0
A18: ENRIQUE | C18: D1 | F18: D1 | G18: D1 | K18: D1 | L18: D1 | O18: D1 | P18: D1 | Q18: D1 | T18: D1 | U18: D1 | Y18: D1 | Z18: D1 | AC18: D1 | AD18: D1 | AH18: =SUM(AH149:AH150) -> 168 | AI18: =AH18-C37 -> 6 | AJ18: =SUM(C154:AG154) -> 48 | AK18: =AK41 -> 0 | AL18: =SUM(C155:AG155) -> 0
AH19: =SUM(AH160:AH161) -> 0 | AI19: =AH19-C37 -> -162 | AJ19: =SUM(C165:AG165) -> 0 | AK19: =AK42 -> 0 | AL19: =SUM(C166:AG166) -> 0
AH20: =SUM(AH171:AH172) -> 0 | AI20: =AH20-C37 -> -162 | AJ20: =SUM(C176:AG176) -> 0 | AK20: =AK43 -> 0 | AL20: =SUM(C177:AG177) -> 0
B21: SUMAS | C21: =SUM(C51+C62+C73+C84+C95+C106+C117+C128+C139+C150+C161+C172) -> 36 | D21: =SUM(D51+D62+D73+D84+D95+D106+D117+D128+D139+D150+D161+D172) -> 36 | E21: =SUM(E51+E62+E73+E84+E95+E106+E117+E128+E139+E150+E161+E172) -> 36 | F21: =SUM(F51+F62+F73+F84+F95+F106+F117+F128+F139+F150+F161+F172) -> 36 | G21: =SUM(G51+G62+G73+G84+G95+G106+G117+G128+G139+G150+G161+G172) -> 36 | H21: =SUM(H51+H62+H73+H84+H95+H106+H117+H128+H139+H150+H161+H172) -> 36 | I21: =SUM(I51+I62+I73+I84+I95+I106+I117+I128+I139+I150+I161+I172) -> 36 | J21: =SUM(J51+J62+J73+J84+J95+J106+J117+J128+J139+J150+J161+J172) -> 36 | ... AG21: =SUM(AG51+AG62+AG73+AG84+AG95+AG106+AG117+AG128+AG139+AG150+AG161+AG172) -> 0
C23: TURNOS | J23: TURNOS | Q23: JORNADA PARTIDA | AQ23: 5 < 10 el 5 es menor que 10
C24: =R32 -> D1 | D24: =S32 -> 0.25 | F24: A | G24: =V32 -> 0.75 | J24: =R35 -> N2 | K24: =S35 -> 0.79166667 | M24: A | N24: =V35 -> 0.29166667 | Q24: =R38 -> G | T24: A | Y24: A | AG24: X | AH24: FESTIVO | AQ24: 10 > 3 el 10 es mayor que 3
C25: =R33 -> N1 | D25: =S33 -> 0.75 | F25: A | G25: =V33 -> 0.25 | J25: =R36 -> N3 | K25: =S36 -> 0.91666667 | M25: A | N25: =V36 -> 0.25 | Q25: =R39 -> H | T25: A | Y25: A | AG25: V | AH25: VACACIONES | AQ25: 1 > 0 1 es mayor que cero
C26: =R34 -> D2 | D26: =S34 -> 0.29166667 | F26: A | G26: =V34 -> 0.79166667 | J26: =R37 -> F | K26: =S37 -> 0.20833333 | M26: A | N26: =V37 -> 0.25 | Q26: =R40 -> I | T26: A | Y26: A | AG26: PR | AH26: P. RETRIBUIDO | AQ26: -5 < 0 negativo 5 es menor que cero
B29: NOTAS: | C29: =E43 -> *Aquí notas que se vean en el cuadrante...
AN30: AN | AP30: AP | AQ30: AQ | AX30: AX | AZ30: AZ | BD30: b
A31: CONFIGURACION CUADRANTE | R31: TURNOS | AD31: CALCULAR MINUTOS | AK31: NOC | AN31: NOCTUR. | AO31: T. HORAS | AP31: ENTRADA | AQ31: SALIDA | AR31: CONDICIONES DE NOCTURNIDAD | BA31: SUMA HR. | BB31: CALCULO HORAS | BD31: NOCTURNIDAD
A32: EMPRESA | C32: =CONTROL!B34 -> EMPRESA | R32: D1 | S32: 0.25 | U32: A | V32: 0.75 | AD32: MINUTOS | AH32: 0.5 | AI32: =AH32/24 -> 0.020833333 | AK32: =AH49 -> 112 | AL32: V1 | AN32: =IF(AS32/24=0,0,AS32/24) -> 0 | AO32: =IF(BA32=0,"",BA32) -> 0.5 | AP32: =S32*24 -> 6 | AQ32: =V32*24 -> 18 | AR32: =AS32 -> 0 | AS32: =IF(AV32>=4,AT32,AT32) -> 0 | AT32: =IF(AV32>8,8,AU32) -> 0 | AU32: =IF(AV32<0,0,AV32) -> 0 | AV32: =IF(AP32=AQ32,0,IF(AP32>AQ32,AW32,IF(AP32>=6,AX32,AQ32-AP32))) -> -12 | AW32: =IF(AP32<6,(AQ32-22+24)+(6-AP32),IF(AP32>=22,AY32,IF(AV2<=6,(AQ32-22)+24,8))) -> 20 | AX32: =IF(AQ32>22,AZ32,IF(AP32<AQ32,AP32-AQ32,IF(AP32>6,0,(6-AP32)))) -> -12 | AY32: =IF(AQ32<=6,(AQ32-AP32)+24,IF(AQ32>22,8,(6-AP32)+24)) -> 24 | AZ32: =IF(AP32<=6,(6-AP32)+(AQ32-22),IF(AP32>22,(AQ32-AP32),(AQ32-22))) -> -4 | BA32: =IF(V32-S32>=0,V32-S32,V32-S32+24) -> 0.5 | BB32: =IF(AO32<1,AO32*24,(AO32-24)*24) -> 12 | BC32: =IF(BB32>=0,BB32,BB32+24) -> 12 | BD32: =IF(AX32<=0,AN32,IF(AX32>=0.1,AX32/24)) -> 0 | BE32: =IF(BD38>=4,IF(BD38="",0,8),IF(BD38>=0.1,IF(BD38="",0,BD38),""))
A33: CENTRO | C33: =CONTROL!B35 -> CENTRO | R33: N1 | S33: 0.75 | U33: A | V33: 0.25 | AK33: =AH60 -> 112 | AL33: V2 | AN33: =IF(AS33/24=0,0,AS33/24) -> 0.33333333 | AO33: =IF(BA33=0,"",BA33) -> 23.5 | AP33: =S33*24 -> 18 | AQ33: =V33*24 -> 6 | AR33: =AS33 -> 8 | AS33: =IF(AV33>=4,AT33,AT33) -> 8 | AT33: =IF(AV33>8,8,AU33) -> 8 | AU33: =IF(AV33<0,0,AV33) -> 8 | AV33: =IF(AP33=AQ33,0,IF(AP33>AQ33,AW33,IF(AP33>=6,AX33,AQ33-AP33))) -> 8 | AW33: =IF(AP33<6,(AQ33-22+24)+(6-AP33),IF(AP33>=22,AY33,IF(AV3<=6,(AQ33-22)+24,8))) -> 8 | AX33: =IF(AQ33>22,AZ33,IF(AP33<AQ33,AP33-AQ33,IF(AP33>6,0,(6-AP33)))) -> 0 | AY33: =IF(AQ33<=6,(AQ33-AP33)+24,IF(AQ33>22,8,(6-AP33)+24)) -> 12 | AZ33: =IF(AP33<=6,(6-AP33)+(AQ33-22),IF(AP33>22,(AQ33-AP33),(AQ33-22))) -> -16 | BA33: =IF(V33-S33>=0,V33-S33,V33-S33+24) -> 23.5 | BB33: =IF(AO33<1,AO33*24,(AO33-24)*24) -> -12 | BC33: =IF(BB33>=0,BB33,BB33+24) -> 12 | BD33: =IF(AX33<=0,AN33,IF(AX33>=0.1,AX33/24)) -> 0.33333333 | BE33: =IF(BD39>=4,IF(BD39="",0,8),IF(BD39>=0.1,IF(BD39="",0,BD39),""))
A34: AÑO | C34: 2026 | R34: D2 | S34: 0.29166667 | U34: A | V34: 0.79166667 | AK34: =AH71 -> 0 | AL34: V3 | AN34: =IF(AS34/24=0,0,AS34/24) -> 0 | AO34: =IF(BA34=0,"",BA34) -> 0.5 | AP34: =S34*24 -> 7 | AQ34: =V34*24 -> 19 | AR34: =AS34 -> 0 | AS34: =IF(AV34>=4,AT34,AT34) -> 0 | AT34: =IF(AV34>8,8,AU34) -> 0 | AU34: =IF(AV34<0,0,AV34) -> 0 | AV34: =IF(AP34=AQ34,0,IF(AP34>AQ34,AW34,IF(AP34>=6,AX34,AQ34-AP34))) -> -12 | AW34: =IF(AP34<6,(AQ34-22+24)+(6-AP34),IF(AP34>=22,AY34,IF(AV4<=6,(AQ34-22)+24,8))) -> 21 | AX34: =IF(AQ34>22,AZ34,IF(AP34<AQ34,AP34-AQ34,IF(AP34>6,0,(6-AP34)))) -> -12 | AY34: =IF(AQ34<=6,(AQ34-AP34)+24,IF(AQ34>22,8,(6-AP34)+24)) -> 23 | AZ34: =IF(AP34<=6,(6-AP34)+(AQ34-22),IF(AP34>22,(AQ34-AP34),(AQ34-22))) -> -3 | BA34: =IF(V34-S34>=0,V34-S34,V34-S34+24) -> 0.5 | BB34: =IF(AO34<1,AO34*24,(AO34-24)*24) -> 12 | BC34: =IF(BB34>=0,BB34,BB34+24) -> 12 | BD34: =IF(AX34<=0,AN34,IF(AX34>=0.1,AX34/24)) -> 0 | BE34: =IF(BD40>=4,IF(BD40="",0,8),IF(BD40>=0.1,IF(BD40="",0,BD40),""))
A35: MES | C35: 2 | R35: N2 | S35: 0.79166667 | U35: A | V35: 0.29166667 | AK35: =AH82 -> 0 | AL35: V4 | AN35: =IF(AS35/24=0,0,AS35/24) -> 0.33333333 | AO35: =IF(BA35=0,"",BA35) -> 23.5 | AP35: =S35*24 -> 19 | AQ35: =V35*24 -> 7 | AR35: =AS35 -> 8 | AS35: =IF(AV35>=4,AT35,AT35) -> 8 | AT35: =IF(AV35>8,8,AU35) -> 8 | AU35: =IF(AV35<0,0,AV35) -> 9 | AV35: =IF(AP35=AQ35,0,IF(AP35>AQ35,AW35,IF(AP35>=6,AX35,AQ35-AP35))) -> 9 | AW35: =IF(AP35<6,(AQ35-22+24)+(6-AP35),IF(AP35>=22,AY35,IF(AV5<=6,(AQ35-22)+24,8))) -> 9 | AX35: =IF(AQ35>22,AZ35,IF(AP35<AQ35,AP35-AQ35,IF(AP35>6,0,(6-AP35)))) -> 0 | AY35: =IF(AQ35<=6,(AQ35-AP35)+24,IF(AQ35>22,8,(6-AP35)+24)) -> 11 | AZ35: =IF(AP35<=6,(6-AP35)+(AQ35-22),IF(AP35>22,(AQ35-AP35),(AQ35-22))) -> -15 | BA35: =IF(V35-S35>=0,V35-S35,V35-S35+24) -> 23.5 | BB35: =IF(AO35<1,AO35*24,(AO35-24)*24) -> -12 | BC35: =IF(BB35>=0,BB35,BB35+24) -> 12 | BD35: =IF(AX35<=0,AN35,IF(AX35>=0.1,AX35/24)) -> 0.33333333
A36: VACACIONES | C36: 5.22 | R36: N3 | S36: 0.91666667 | U36: A | V36: 0.25 | AK36: =AH93 -> 0 | AL36: V5 | AN36: =IF(AS36/24=0,0,AS36/24) -> 0.33333333 | AO36: =IF(BA36=0,"",BA36) -> 23.333333 | AP36: =S36*24 -> 22 | AQ36: =V36*24 -> 6 | AR36: =AS36 -> 8 | AS36: =IF(AV36>=4,AT36,AT36) -> 8 | AT36: =IF(AV36>8,8,AU36) -> 8 | AU36: =IF(AV36<0,0,AV36) -> 8 | AV36: =IF(AP36=AQ36,0,IF(AP36>AQ36,AW36,IF(AP36>=6,AX36,AQ36-AP36))) -> 8 | AW36: =IF(AP36<6,(AQ36-22+24)+(6-AP36),IF(AP36>=22,AY36,IF(AV6<=6,(AQ36-22)+24,8))) -> 8 | AX36: =IF(AQ36>22,AZ36,IF(AP36<AQ36,AP36-AQ36,IF(AP36>6,0,(6-AP36)))) -> 0 | AY36: =IF(AQ36<=6,(AQ36-AP36)+24,IF(AQ36>22,8,(6-AP36)+24)) -> 8 | AZ36: =IF(AP36<=6,(6-AP36)+(AQ36-22),IF(AP36>22,(AQ36-AP36),(AQ36-22))) -> -16 | BA36: =IF(V36-S36>=0,V36-S36,V36-S36+24) -> 23.333333 | BB36: =IF(AO36<1,AO36*24,(AO36-24)*24) -> -16 | BC36: =IF(BB36>=0,BB36,BB36+24) -> 8 | BD36: =IF(AX36<=0,AN36,IF(AX36>=0.1,AX36/24)) -> 0.33333333
A37: JORNADA | C37: 162 | R37: =CONTROL!F40 -> F | S37: =CONTROL!G40 -> 0.20833333 | U37: A | V37: =CONTROL!H40 -> 0.25 | AK37: =AH104 -> 0 | AL37: V6 | AN37: =IF(AS37/24=0,0,AS37/24) -> 0.041666667 | AO37: =IF(BA37=0,"",BA37) -> 0.041666667 | AP37: =S37*24 -> 5 | AQ37: =V37*24 -> 6 | AR37: =AS37 -> 1 | AS37: =IF(AV37>=4,AT37,AT37) -> 1 | AT37: =IF(AV37>8,8,AU37) -> 1 | AU37: =IF(AV37<0,0,AV37) -> 1 | AV37: =IF(AP37=AQ37,0,IF(AP37>AQ37,AW37,IF(AP37>=6,AX37,AQ37-AP37))) -> 1 | AW37: =IF(AP37<6,(AQ37-22+24)+(6-AP37),IF(AP37>=22,AY37,IF(AV7<=6,(AQ37-22)+24,8))) -> 9 | AX37: =IF(AQ37>22,AZ37,IF(AP37<AQ37,AP37-AQ37,IF(AP37>6,0,(6-AP37)))) -> -1 | AY37: =IF(AQ37<=6,(AQ37-AP37)+24,IF(AQ37>22,8,(6-AP37)+24)) -> 25 | AZ37: =IF(AP37<=6,(6-AP37)+(AQ37-22),IF(AP37>22,(AQ37-AP37),(AQ37-22))) -> -15 | BA37: =IF(V37-S37>=0,V37-S37,V37-S37+24) -> 0.041666667 | BB37: =IF(AO37<1,AO37*24,(AO37-24)*24) -> 1 | BC37: =IF(BB37>=0,BB37,BB37+24) -> 1 | BD37: =IF(AX37<=0,AN37,IF(AX37>=0.1,AX37/24)) -> 0.041666667
A38: P. RETRIBUIDO | C38: 0 | R38: =CONTROL!F41 -> G | S38: =CONTROL!G41 -> 0.29166667 | U38: A | V38: =CONTROL!H41 -> 0.33333333 | AK38: =AH115 -> 0 | AL38: V7 | AN38: =IF(AS38/24=0,0,AS38/24) -> 0 | AO38: =IF(BA38=0,"",BA38) -> 0.041666667 | AP38: =S38*24 -> 7 | AQ38: =V38*24 -> 8 | AR38: =AS38 -> 0 | AS38: =IF(AV38>=4,AT38,AT38) -> 0 | AT38: =IF(AV38>8,8,AU38) -> 0 | AU38: =IF(AV38<0,0,AV38) -> 0 | AV38: =IF(AP38=AQ38,0,IF(AP38>AQ38,AW38,IF(AP38>=6,AX38,AQ38-AP38))) -> -1 | AW38: =IF(AP38<6,(AQ38-22+24)+(6-AP38),IF(AP38>=22,AY38,IF(AV8<=6,(AQ38-22)+24,8))) -> 10 | AX38: =IF(AQ38>22,AZ38,IF(AP38<AQ38,AP38-AQ38,IF(AP38>6,0,(6-AP38)))) -> -1 | AY38: =IF(AQ38<=6,(AQ38-AP38)+24,IF(AQ38>22,8,(6-AP38)+24)) -> 23 | AZ38: =IF(AP38<=6,(6-AP38)+(AQ38-22),IF(AP38>22,(AQ38-AP38),(AQ38-22))) -> -14 | BA38: =IF(V38-S38>=0,V38-S38,V38-S38+24) -> 0.041666667 | BB38: =IF(AO38<1,AO38*24,(AO38-24)*24) -> 1 | BC38: =IF(BB38>=0,BB38,BB38+24) -> 1 | BD38: =IF(AX38<=0,AN38,IF(AX38>=0.1,AX38/24)) -> 0
R39: =CONTROL!F42 -> H | S39: =CONTROL!G42 -> 0.33333333 | U39: A | V39: =CONTROL!H42 -> 0.375 | AK39: =AH126 -> 0 | AL39: V8 | AN39: =IF(AS39/24=0,0,AS39/24) -> 0 | AO39: =IF(BA39=0,"",BA39) -> 0.041666667 | AP39: =S39*24 -> 8 | AQ39: =V39*24 -> 9 | AR39: =AS39 -> 0 | AS39: =IF(AV39>=4,AT39,AT39) -> 0 | AT39: =IF(AV39>8,8,AU39) -> 0 | AU39: =IF(AV39<0,0,AV39) -> 0 | AV39: =IF(AP39=AQ39,0,IF(AP39>AQ39,AW39,IF(AP39>=6,AX39,AQ39-AP39))) -> -1 | AW39: =IF(AP39<6,(AQ39-22+24)+(6-AP39),IF(AP39>=22,AY39,IF(AV9<=6,(AQ39-22)+24,8))) -> 11 | AX39: =IF(AQ39>22,AZ39,IF(AP39<AQ39,AP39-AQ39,IF(AP39>6,0,(6-AP39)))) -> -1 | AY39: =IF(AQ39<=6,(AQ39-AP39)+24,IF(AQ39>22,8,(6-AP39)+24)) -> 22 | AZ39: =IF(AP39<=6,(6-AP39)+(AQ39-22),IF(AP39>22,(AQ39-AP39),(AQ39-22))) -> -13 | BA39: =IF(V39-S39>=0,V39-S39,V39-S39+24) -> 0.041666667 | BB39: =IF(AO39<1,AO39*24,(AO39-24)*24) -> 1 | BC39: =IF(BB39>=0,BB39,BB39+24) -> 1 | BD39: =IF(AX39<=0,AN39,IF(AX39>=0.1,AX39/24)) -> 0
R40: =CONTROL!F43 -> I | S40: =CONTROL!G43 -> 0.41666667 | U40: A | V40: =CONTROL!H43 -> 0.45833333 | AK40: =AH137 -> 0 | AL40: V9 | AN40: =IF(AS40/24=0,0,AS40/24) -> 0 | AO40: =IF(BA40=0,"",BA40) -> 0.041666667 | AP40: =S40*24+24 -> 34 | AQ40: =V40*24 -> 11 | AR40: =AS40 -> 0 | AS40: =IF(AV40>=4,AT40,AT40) -> 0 | AT40: =IF(AV40>8,8,AU40) -> 0 | AU40: =IF(AV40<0,0,AV40) -> 0 | AV40: =IF(AP40=AQ40,0,IF(AP40>AQ40,AW40,IF(AP40>=6,AX40,AQ40-AP40))) -> -4 | AW40: =IF(AP40<6,(AQ40-22+24)+(6-AP40),IF(AP40>=22,AY40,IF(AV10<=6,(AQ40-22)+24,8))) -> -4 | AX40: =IF(AQ40>22,AZ40,IF(AP40<AQ40,AP40-AQ40,IF(AP40>6,0,(6-AP40)))) -> 0 | AY40: =IF(AQ40<=6,(AQ40-AP40)+24,IF(AQ40>22,8,(6-AP40)+24)) -> -4 | AZ40: =IF(AP40<=6,(6-AP40)+(AQ40-22),IF(AP40>22,(AQ40-AP40),(AQ40-22))) -> -23 | BA40: =IF(V40-S40>=0,V40-S40,V40-S40+24) -> 0.041666667 | BB40: =IF(AO40<1,AO40*24,(AO40-24)*24) -> 1 | BC40: =IF(BB40>=0,BB40,BB40+24) -> 1 | BD40: =IF(AX40<=0,AN40,IF(AX40>=0.1,AX40/24)) -> 0
AK41: =AH148 -> 0 | AL41: V10 | AP41: =S41*24 -> 0 | AR41: 1 | AS41: 2 | AT41: 3 | AU41: 4 | AV41: 5 | AW41: 6 | AX41: 7 | AY41: 8 | AZ41: 9
C42: http://oscar.org.es | W42: =CONTROL!B38 -> OSCAR ORGEIRA © 20.03.00 EXCEL | AK42: =AH159 -> 0 | AL42: V11
C43: notas | E43: *Aquí notas que se vean en el cuadrante... | AK43: =AH170 -> 0 | AL43: V12
BE44: =INDEX({"do";"lu";"ma";"mi";"ju";"vi";"sa"},1+MOD($AR$47+4-2,7)) -> ju
B45: FEST. FINDE | C45: =IF(C7="S",IF(C7="",0,1),IF(C7="D",IF(C7="",0,1),"")) -> 1 | D45: =IF(D7="S",IF(D7="",0,1),IF(D7="D",IF(D7="",0,1),"")) | E45: =IF(E7="S",IF(E7="",0,1),IF(E7="D",IF(E7="",0,1),"")) | F45: =IF(F7="S",IF(F7="",0,1),IF(F7="D",IF(F7="",0,1),"")) | G45: =IF(G7="S",IF(G7="",0,1),IF(G7="D",IF(G7="",0,1),"")) | H45: =IF(H7="S",IF(H7="",0,1),IF(H7="D",IF(H7="",0,1),"")) | I45: =IF(I7="S",IF(I7="",0,1),IF(I7="D",IF(I7="",0,1),"")) -> 1 | J45: =IF(J7="S",IF(J7="",0,1),IF(J7="D",IF(J7="",0,1),"")) -> 1 | ... AH45: =IF(AH7="S",IF(AH7="",0,1),IF(AH7="D",IF(AH7="",0,1),"")) | AI45: SUMAS | BE45: =IF(MONTH($Q$4)<>MONTH($Q$4-(WEEKDAY($Q$4,1)-($AR$47-1))-IF((WEEKDAY($Q$4,1)-($AR$47-1))<=0,7,0)+(ROW(BE45)-ROW($AN$51))*7+(COLUMN(BE45)-COLUMN($AN$51)+1)),"",$Q$4-(WEEKDAY($Q$4,1)-($AR$47-1))-IF((WEEKDAY($Q$4,1)-($AR$47-1))<=0,7,0)+(ROW(BE45)-ROW($AN$51))*7+(COLUMN(BE45)-COLUMN($AN$51)+1))
...

Sheet MARZO
B3: =C32 -> EMPRESA
B4: =C33 -> CENTRO | Q4: =DATE($C$34,$C$35,1) -> 46082 | Z4: =SUM(AH51+AH62+AH73+AH84+AH95+AH106+AH117+AH128+AH139+AH150+AH161+AH172) -> 1736 | AC4: h. centro
AE5: =IF(CA59=28,IF(CA59="",0,1),IF(CA59=1,IF(CA59="",0,1),"")) | AF5: =IF(CA59=29,IF(CA59="",0,1),IF(CA59=1,IF(CA59="",0,1),"")) | AG5: =IF(CA59=30,IF(CA59="",0,1),IF(CA59=1,IF(CA59="",0,1),"")) | AH5: =IF(CA59=31,IF(CA59="",0,1),IF(CA59=1,IF(CA59="",0,1),"")) -> 1
B6: FESTIVO
B7: DIA SEM. | C7: =IF(AV47="LUNES","lu",IF(AV47="MARTES","ma",IF(AV47="MIERCOLES","mi",IF(AV47="JUEVES","ju",IF(AV47="VIERNES","vi",IF(AV47="SABADO","S",IF(AV47="DOMINGO","D",""))))))) -> D | D7: =IF(C7="lu","ma",IF(C7="ma","mi",IF(C7="mi","ju",IF(C7="ju","vi",IF(C7="vi","S",IF(C7="S","D",IF(C7="D","lu",""))))))) -> lu | E7: =IF(D7="lu","ma",IF(D7="ma","mi",IF(D7="mi","ju",IF(D7="ju","vi",IF(D7="vi","S",IF(D7="S","D",IF(D7="D","lu",""))))))) -> ma | F7: =IF(E7="lu","ma",IF(E7="ma","mi",IF(E7="mi","ju",IF(E7="ju","vi",IF(E7="vi","S",IF(E7="S","D",IF(E7="D","lu",""))))))) -> mi | G7: =IF(F7="lu","ma",IF(F7="ma","mi",IF(F7="mi","ju",IF(F7="ju","vi",IF(F7="vi","S",IF(F7="S","D",IF(F7="D","lu",""))))))) -> ju | H7: =IF(G7="lu","ma",IF(G7="ma","mi",IF(G7="mi","ju",IF(G7="ju","vi",IF(G7="vi","S",IF(G7="S","D",IF(G7="D","lu",""))))))) -> vi | I7: =IF(H7="lu","ma",IF(H7="ma","mi",IF(H7="mi","ju",IF(H7="ju","vi",IF(H7="vi","S",IF(H7="S","D",IF(H7="D","lu",""))))))) -> S | J7: =IF(I7="lu","ma",IF(I7="ma","mi",IF(I7="mi","ju",IF(I7="ju","vi",IF(I7="vi","S",IF(I7="S","D",IF(I7="D","lu",""))))))) -> D | K7: =IF(J7="lu","ma",IF(J7="ma","mi",IF(J7="mi","ju",IF(J7="ju","vi",IF(J7="vi","S",IF(J7="S","D",IF(J7="D","lu",""))))))) -> lu | ... AD7: =IF(AC7="lu","ma",IF(AC7="ma","mi",IF(AC7="mi","ju",IF(AC7="ju","vi",IF(AC7="vi","S",IF(AC7="S","D",IF(AC7="D","lu",""))))))) -> S | AE7: =IF(AE8="","",IF(AD7="lu","ma",IF(AD7="ma","mi",IF(AD7="mi","ju",IF(AD7="ju","vi",IF(AD7="vi","S",IF(AD7="S","D",IF(AD7="D","lu","")))))))) -> D | AF7: =IF(AF8="","",IF(AE7="lu","ma",IF(AE7="ma","mi",IF(AE7="mi","ju",IF(AE7="ju","vi",IF(AE7="vi","S",IF(AE7="S","D",IF(AE7="D","lu","")))))))) -> lu | AG7: =IF(AG8="","",IF(AF7="lu","ma",IF(AF7="ma","mi",IF(AF7="mi","ju",IF(AF7="ju","vi",IF(AF7="vi","S",IF(AF7="S","D",IF(AF7="D","lu","")))))))) -> ma
A8: VIGILANTE Nº | C8: 1 | D8: 2 | E8: 3 | F8: 4 | G8: 5 | H8: 6 | I8: 7 | J8: 8 | K8: 9 | L8: 10 | M8: 11 | N8: 12 | O8: 13 | P8: 14 | Q8: 15 | R8: 16 | S8: 17 | T8: 18 | U8: 19 | V8: 20 | W8: 21 | X8: 22 | Y8: 23 | Z8: 24 | AA8: 25 | AB8: 26 | AC8: 27 | AD8: 28 | AE8: =IF(CA59=28,"",IF(CA59=29,29,IF(CA59=30,29,IF(CA59=31,29,"")))) -> 29 | AF8: =IF(CA59=28,"",IF(CA59=29,"",IF(CA59=30,30,IF(CA59=31,30,"")))) -> 30 | AG8: =IF(CA59=28,"",IF(CA59=29,"",IF(CA59=30,"",IF(CA59=31,31,"")))) -> 31 | AH8: HORAS | AI8: EXT | AJ8: FES | AK8: NOC | AL8: DV
A9: JAVI | D9: N2 | E9: N2 | F9: N1 | K9: N3 | L9: N3 | M9: N2 | N9: N2 | R9: N2 | S9: N2 | U9: N3 | V9: N2 | W9: N2 | X9: N2 | Y9: N1 | AA9: N2 | AB9: N2 | AF9: N2 | AG9: N2 | AH9: =SUM(AH50:AH51) -> 204 | AI9: =AH9-C37 -> 42 | AJ9: =SUM(C55:AG55) -> 24 | AK9: =AK32 -> 144 | AL9: =SUM(C56:AG56) -> 0 | CB9: =ROUNDDOWN(AH9,0) -> 204 | CC9: =AH9-INT(AH9) -> 0 | CD9: =CC9/24 -> 0
A10: PAREDES | C10: N2 | F10: N2 | G10: N2 | K10: N2 | L10: N2 | O10: N2 | P10: N2 | Q10: N2 | T10: N2 | U10: N2 | Y10: N2 | Z10: N2 | AC10: N2 | AD10: N2 | AE10: N2 | AH10: =SUM(AH61:AH62) -> 180 | AI10: =AH10-C37 -> 18 | AJ10: =SUM(C66:AG66) -> 53 | AK10: =AK33 -> 120 | AL10: =SUM(C67:AG67) -> 0
A11: JUAN | C11: B | D11: B | E11: B | F11: B | G11: B | H11: B | I11: B | J11: B | K11: B | L11: B | M11: B | N11: B | O11: B | P11: B | Q11: B | R11: B | S11: B | T11: B | U11: B | V11: B | W11: B | X11: B | Y11: B | Z11: B | AA11: B | AB11: B | AC11: B | AD11: B | AE11: B | AF11: B | AG11: B | AH11: =SUM(AH72:AH73) -> 0 | AI11: =AH11-C37 -> -162 | AJ11: =SUM(C77:AG77) -> 0 | AK11: =AK34 -> 0 | AL11: =SUM(C78:AG78) -> 0
A12: MILOU | D12: D2 | E12: D2 | H12: D2 | I12: D2 | J12: D2 | M12: D2 | N12: D2 | R12: D2 | S12: D2 | AA12: D2 | AB12: D2 | AC12: D2 | AD12: D2 | AE12: D2 | AF12: D2 | AG12: D2 | AH12: =SUM(AH83:AH84) -> 192 | AI12: =AH12-C37 -> 30 | AJ12: =SUM(C88:AG88) -> 48 | AK12: =AK35 -> 0 | AL12: =SUM(C89:AG89) -> 0
A13: X | C13: N3 | F13: N3 | G13: N3 | H13: N3 | I13: N3 | J13: N3 | M13: N3 | N13: N3 | O13: N3 | P13: N3 | Q13: N3 | R13: N3 | S13: N3 | T13: N3 | Y13: N3 | Z13: N3 | AB13: N3 | AC13: N3 | AD13: N3 | AE13: N3 | AF13: N3 | AG13: N3 | AH13: =SUM(AH94:AH95) -> 176 | AI13: =AH13-C37 -> 14 | AJ13: =SUM(C99:AG99) -> 50 | AK13: =AK36 -> 176 | AL13: =SUM(C100:AG100) -> 0
A14: HIDALGO | D14: D1 | E14: D1 | H14: D1 | I14: D1 | J14: D1 | M14: D1 | N14: D1 | R14: D1 | S14: D1 | V14: D1 | W14: D1 | X14: D1 | Y14: D2 | AA14: D1 | AB14: D1 | AF14: D1 | AG14: D1 | AH14: =SUM(AH105:AH106) -> 204 | AI14: =AH14-C37 -> 42 | AJ14: =SUM(C110:AG110) -> 48 | AK14: =AK37 -> 0 | AL14: =SUM(C111:AG111) -> 0
A15: SAMUEL | C15: D2 | D15: N1 | E15: N1 | H15: N2 | I15: N2 | J15: N2 | K15: N1 | L15: N1 | M15: N1 | N15: N1 | O15: L | P15: L | Q15: L | T15: D2 | U15: D2 | V15: D2 | W15: D2 | X15: D2 | Z15: D2 | AA15: N1 | AC15: L | AD15: L | AE15: L | AF15: N1 | AG15: N1 | AH15: =SUM(AH116:AH117) -> 228 | AI15: =AH15-C37 -> 66 | AJ15: =SUM(C121:AG121) -> 60 | AK15: =AK38 -> 96 | AL15: =SUM(C122:AG122) -> 0
A16: PAREJO | C16: N1 | F16: D2 | G16: D2 | K16: D2 | L16: D2 | O16: D2 | P16: D2 | Q16: D2 | S16: N1 | T16: N1 | U16: N1 | V16: N1 | W16: N1 | X16: N1 | AA16: N3 | AB16: N1 | AH16: =SUM(AH127:AH128) -> 188 | AI16: =AH16-C37 -> 26 | AJ16: =SUM(C132:AG132) -> 54 | AK16: =AK39 -> 72 | AL16: =SUM(C133:AG133) -> 0
A17: PEDREÑO | D17: N3 | E17: N3 | G17: N1 | H17: N1 | I17: N1 | J17: N1 | O17: N1 | P17: N1 | Q17: N1 | R17: N1 | V17: N3 | W17: N3 | X17: N3 | Z17: N1 | AC17: N1 | AD17: N1 | AE17: N1 | AH17: =SUM(AH138:AH139) -> 184 | AI17: =AH17-C37 -> 22 | AJ17: =SUM(C143:AG143) -> 88 | AK17: =AK40 -> 136 | AL17: =SUM(C144:AG144) -> 0
A18: ENRIQUE | C18: D1 | F18: D1 | G18: D1 | K18: D1 | L18: D1 | O18: D1 | P18: D1 | Q18: D1 | T18: D1 | U18: D1 | Y18: D1 | Z18: D1 | AC18: D1 | AD18: D1 | AE18: D1 | AH18: =SUM(AH149:AH150) -> 180 | AI18: =AH18-C37 -> 18 | AJ18: =SUM(C154:AG154) -> 60 | AK18: =AK41 -> 0 | AL18: =SUM(C155:AG155) -> 0
AH19: =SUM(AH160:AH161) -> 0 | AI19: =AH19-C37 -> -162 | AJ19: =SUM(C165:AG165) -> 0 | AK19: =AK42 -> 0 | AL19: =SUM(C166:AG166) -> 0
AH20: =SUM(AH171:AH172) -> 0 | AI20: =AH20-C37 -> -162 | AJ20: =SUM(C176:AG176) -> 0 | AK20: =AK43 -> 0 | AL20: =SUM(C177:AG177) -> 0
B21: SUMAS | C21: =SUM(C51+C62+C73+C84+C95+C106+C117+C128+C139+C150+C161+C172) -> 56 | D21: =SUM(D51+D62+D73+D84+D95+D106+D117+D128+D139+D150+D161+D172) -> 56 | E21: =SUM(E51+E62+E73+E84+E95+E106+E117+E128+E139+E150+E161+E172) -> 56 | F21: =SUM(F51+F62+F73+F84+F95+F106+F117+F128+F139+F150+F161+F172) -> 56 | G21: =SUM(G51+G62+G73+G84+G95+G106+G117+G128+G139+G150+G161+G172) -> 56 | H21: =SUM(H51+H62+H73+H84+H95+H106+H117+H128+H139+H150+H161+H172) -> 56 | I21: =SUM(I51+I62+I73+I84+I95+I106+I117+I128+I139+I150+I161+I172) -> 56 | J21: =SUM(J51+J62+J73+J84+J95+J106+J117+J128+J139+J150+J161+J172) -> 56 | ... AG21: =SUM(AG51+AG62+AG73+AG84+AG95+AG106+AG117+AG128+AG139+AG150+AG161+AG172) -> 56
C23: TURNOS | J23: TURNOS | Q23: JORNADA PARTIDA | AQ23: 5 < 10 el 5 es menor que 10
C24: =R32 -> D1 | D24: =S32 -> 0.25 | F24: A | G24: =V32 -> 0.75 | J24: =R35 -> N2 | K24: =S35 -> 0.79166667 | M24: A | N24: =V35 -> 0.29166667 | Q24: =R38 -> G | T24: A | Y24: A | AG24: X | AH24: FESTIVO | AQ24: 10 > 3 el 10 es mayor que 3
C25: =R33 -> N1 | D25: =S33 -> 0.75 | F25: A | G25: =V33 -> 0.25 | J25: =R36 -> N3 | K25: =S36 -> 0.91666667 | M25: A | N25: =V36 -> 0.25 | Q25: =R39 -> H | T25: A | Y25: A | AG25: V | AH25: VACACIONES | AQ25: 1 > 0 1 es mayor que cero
C26: =R34 -> D2 | D26: =S34 -> 0.29166667 | F26: A | G26: =V34 -> 0.79166667 | J26: =R37 -> F | K26: =S37 -> 0.20833333 | M26: A | N26: =V37 -> 0.25 | Q26: =R40 -> I | T26: A | Y26: A | AG26: PR | AH26: P. RETRIBUIDO | AQ26: -5 < 0 negativo 5 es menor que cero
B29: NOTAS: | C29: =E43 -> *Aquí notas que se vean en el cuadrante...
AN30: AN | AP30: AP | AQ30: AQ | AX30: AX | AZ30: AZ | BD30: b
A31: CONFIGURACION CUADRANTE | R31: TURNOS | AD31: CALCULAR MINUTOS | AK31: NOC | AN31: NOCTUR. | AO31: T. HORAS | AP31: ENTRADA | AQ31: SALIDA | AR31: CONDICIONES DE NOCTURNIDAD | BA31: SUMA HR. | BB31: CALCULO HORAS | BD31: NOCTURNIDAD
A32: EMPRESA | C32: =CONTROL!B34 -> EMPRESA | R32: D1 | S32: 0.25 | U32: A | V32: 0.75 | AD32: MINUTOS | AH32: 0.5 | AI32: =AH32/24 -> 0.020833333 | AK32: =AH49 -> 144 | AL32: V1 | AN32: =IF(AS32/24=0,0,AS32/24) -> 0 | AO32: =IF(BA32=0,"",BA32) -> 0.5 | AP32: =S32*24 -> 6 | AQ32: =V32*24 -> 18 | AR32: =AS32 -> 0 | AS32: =IF(AV32>=4,AT32,AT32) -> 0 | AT32: =IF(AV32>8,8,AU32) -> 0 | AU32: =IF(AV32<0,0,AV32) -> 0 | AV32: =IF(AP32=AQ32,0,IF(AP32>AQ32,AW32,IF(AP32>=6,AX32,AQ32-AP32))) -> -12 | AW32: =IF(AP32<6,(AQ32-22+24)+(6-AP32),IF(AP32>=22,AY32,IF(AV2<=6,(AQ32-22)+24,8))) -> 20 | AX32: =IF(AQ32>22,AZ32,IF(AP32<AQ32,AP32-AQ32,IF(AP32>6,0,(6-AP32)))) -> -12 | AY32: =IF(AQ32<=6,(AQ32-AP32)+24,IF(AQ32>22,8,(6-AP32)+24)) -> 24 | AZ32: =IF(AP32<=6,(6-AP32)+(AQ32-22),IF(AP32>22,(AQ32-AP32),(AQ32-22))) -> -4 | BA32: =IF(V32-S32>=0,V32-S32,V32-S32+24) -> 0.5 | BB32: =IF(AO32<1,AO32*24,(AO32-24)*24) -> 12 | BC32: =IF(BB32>=0,BB32,BB32+24) -> 12 | BD32: =IF(AX32<=0,AN32,IF(AX32>=0.1,AX32/24)) -> 0 | BE32: =IF(BD38>=4,IF(BD38="",0,8),IF(BD38>=0.1,IF(BD38="",0,BD38),""))
A33: CENTRO | C33: =CONTROL!B35 -> CENTRO | R33: N1 | S33: 0.75 | U33: A | V33: 0.25 | AK33: =AH60 -> 120 | AL33: V2 | AN33: =IF(AS33/24=0,0,AS33/24) -> 0.33333333 | AO33: =IF(BA33=0,"",BA33) -> 23.5 | AP33: =S33*24 -> 18 | AQ33: =V33*24 -> 6 | AR33: =AS33 -> 8 | AS33: =IF(AV33>=4,AT33,AT33) -> 8 | AT33: =IF(AV33>8,8,AU33) -> 8 | AU33: =IF(AV33<0,0,AV33) -> 8 | AV33: =IF(AP33=AQ33,0,IF(AP33>AQ33,AW33,IF(AP33>=6,AX33,AQ33-AP33))) -> 8 | AW33: =IF(AP33<6,(AQ33-22+24)+(6-AP33),IF(AP33>=22,AY33,IF(AV3<=6,(AQ33-22)+24,8))) -> 8 | AX33: =IF(AQ33>22,AZ33,IF(AP33<AQ33,AP33-AQ33,IF(AP33>6,0,(6-AP33)))) -> 0 | AY33: =IF(AQ33<=6,(AQ33-AP33)+24,IF(AQ33>22,8,(6-AP33)+24)) -> 12 | AZ33: =IF(AP33<=6,(6-AP33)+(AQ33-22),IF(AP33>22,(AQ33-AP33),(AQ33-22))) -> -16 | BA33: =IF(V33-S33>=0,V33-S33,V33-S33+24) -> 23.5 | BB33: =IF(AO33<1,AO33*24,(AO33-24)*24) -> -12 | BC33: =IF(BB33>=0,BB33,BB33+24) -> 12 | BD33: =IF(AX33<=0,AN33,IF(AX33>=0.1,AX33/24)) -> 0.33333333 | BE33: =IF(BD39>=4,IF(BD39="",0,8),IF(BD39>=0.1,IF(BD39="",0,BD39),""))
A34: AÑO | C34: 2026 | R34: D2 | S34: 0.29166667 | U34: A | V34: 0.79166667 | AK34: =AH71 -> 0 | AL34: V3 | AN34: =IF(AS34/24=0,0,AS34/24) -> 0 | AO34: =IF(BA34=0,"",BA34) -> 0.5 | AP34: =S34*24 -> 7 | AQ34: =V34*24 -> 19 | AR34: =AS34 -> 0 | AS34: =IF(AV34>=4,AT34,AT34) -> 0 | AT34: =IF(AV34>8,8,AU34) -> 0 | AU34: =IF(AV34<0,0,AV34) -> 0 | AV34: =IF(AP34=AQ34,0,IF(AP34>AQ34,AW34,IF(AP34>=6,AX34,AQ34-AP34))) -> -12 | AW34: =IF(AP34<6,(AQ34-22+24)+(6-AP34),IF(AP34>=22,AY34,IF(AV4<=6,(AQ34-22)+24,8))) -> 21 | AX34: =IF(AQ34>22,AZ34,IF(AP34<AQ34,AP34-AQ34,IF(AP34>6,0,(6-AP34)))) -> -12 | AY34: =IF(AQ34<=6,(AQ34-AP34)+24,IF(AQ34>22,8,(6-AP34)+24)) -> 23 | AZ34: =IF(AP34<=6,(6-AP34)+(AQ34-22),IF(AP34>22,(AQ34-AP34),(AQ34-22))) -> -3 | BA34: =IF(V34-S34>=0,V34-S34,V34-S34+24) -> 0.5 | BB34: =IF(AO34<1,AO34*24,(AO34-24)*24) -> 12 | BC34: =IF(BB34>=0,BB34,BB34+24) -> 12 | BD34: =IF(AX34<=0,AN34,IF(AX34>=0.1,AX34/24)) -> 0 | BE34: =IF(BD40>=4,IF(BD40="",0,8),IF(BD40>=0.1,IF(BD40="",0,BD40),""))
A35: MES | C35: 3 | R35: N2 | S35: 0.79166667 | U35: A | V35: 0.29166667 | AK35: =AH82 -> 0 | AL35: V4 | AN35: =IF(AS35/24=0,0,AS35/24) -> 0.33333333 | AO35: =IF(BA35=0,"",BA35) -> 23.5 | AP35: =S35*24 -> 19 | AQ35: =V35*24 -> 7 | AR35: =AS35 -> 8 | AS35: =IF(AV35>=4,AT35,AT35) -> 8 | AT35: =IF(AV35>8,8,AU35) -> 8 | AU35: =IF(AV35<0,0,AV35) -> 9 | AV35: =IF(AP35=AQ35,0,IF(AP35>AQ35,AW35,IF(AP35>=6,AX35,AQ35-AP35))) -> 9 | AW35: =IF(AP35<6,(AQ35-22+24)+(6-AP35),IF(AP35>=22,AY35,IF(AV5<=6,(AQ35-22)+24,8))) -> 9 | AX35: =IF(AQ35>22,AZ35,IF(AP35<AQ35,AP35-AQ35,IF(AP35>6,0,(6-AP35)))) -> 0 | AY35: =IF(AQ35<=6,(AQ35-AP35)+24,IF(AQ35>22,8,(6-AP35)+24)) -> 11 | AZ35: =IF(AP35<=6,(6-AP35)+(AQ35-22),IF(AP35>22,(AQ35-AP35),(AQ35-22))) -> -15 | BA35: =IF(V35-S35>=0,V35-S35,V35-S35+24) -> 23.5 | BB35: =IF(AO35<1,AO35*24,(AO35-24)*24) -> -12 | BC35: =IF(BB35>=0,BB35,BB35+24) -> 12 | BD35: =IF(AX35<=0,AN35,IF(AX35>=0.1,AX35/24)) -> 0.33333333
A36: VACACIONES | C36: 5.22 | R36: N3 | S36: 0.91666667 | U36: A | V36: 0.25 | AK36: =AH93 -> 176 | AL36: V5 | AN36: =IF(AS36/24=0,0,AS36/24) -> 0.33333333 | AO36: =IF(BA36=0,"",BA36) -> 23.333333 | AP36: =S36*24 -> 22 | AQ36: =V36*24 -> 6 | AR36: =AS36 -> 8 | AS36: =IF(AV36>=4,AT36,AT36) -> 8 | AT36: =IF(AV36>8,8,AU36) -> 8 | AU36: =IF(AV36<0,0,AV36) -> 8 | AV36: =IF(AP36=AQ36,0,IF(AP36>AQ36,AW36,IF(AP36>=6,AX36,AQ36-AP36))) -> 8 | AW36: =IF(AP36<6,(AQ36-22+24)+(6-AP36),IF(AP36>=22,AY36,IF(AV6<=6,(AQ36-22)+24,8))) -> 8 | AX36: =IF(AQ36>22,AZ36,IF(AP36<AQ36,AP36-AQ36,IF(AP36>6,0,(6-AP36)))) -> 0 | AY36: =IF(AQ36<=6,(AQ36-AP36)+24,IF(AQ36>22,8,(6-AP36)+24)) -> 8 | AZ36: =IF(AP36<=6,(6-AP36)+(AQ36-22),IF(AP36>22,(AQ36-AP36),(AQ36-22))) -> -16 | BA36: =IF(V36-S36>=0,V36-S36,V36-S36+24) -> 23.333333 | BB36: =IF(AO36<1,AO36*24,(AO36-24)*24) -> -16 | BC36: =IF(BB36>=0,BB36,BB36+24) -> 8 | BD36: =IF(AX36<=0,AN36,IF(AX36>=0.1,AX36/24)) -> 0.33333333
A37: JORNADA | C37: 162 | R37: =CONTROL!F40 -> F | S37: =CONTROL!G40 -> 0.20833333 | U37: A | V37: =CONTROL!H40 -> 0.25 | AK37: =AH104 -> 0 | AL37: V6 | AN37: =IF(AS37/24=0,0,AS37/24) -> 0.041666667 | AO37: =IF(BA37=0,"",BA37) -> 0.041666667 | AP37: =S37*24 -> 5 | AQ37: =V37*24 -> 6 | AR37: =AS37 -> 1 | AS37: =IF(AV37>=4,AT37,AT37) -> 1 | AT37: =IF(AV37>8,8,AU37) -> 1 | AU37: =IF(AV37<0,0,AV37) -> 1 | AV37: =IF(AP37=AQ37,0,IF(AP37>AQ37,AW37,IF(AP37>=6,AX37,AQ37-AP37))) -> 1 | AW37: =IF(AP37<6,(AQ37-22+24)+(6-AP37),IF(AP37>=22,AY37,IF(AV7<=6,(AQ37-22)+24,8))) -> 9 | AX37: =IF(AQ37>22,AZ37,IF(AP37<AQ37,AP37-AQ37,IF(AP37>6,0,(6-AP37)))) -> -1 | AY37: =IF(AQ37<=6,(AQ37-AP37)+24,IF(AQ37>22,8,(6-AP37)+24)) -> 25 | AZ37: =IF(AP37<=6,(6-AP37)+(AQ37-22),IF(AP37>22,(AQ37-AP37),(AQ37-22))) -> -15 | BA37: =IF(V37-S37>=0,V37-S37,V37-S37+24) -> 0.041666667 | BB37: =IF(AO37<1,AO37*24,(AO37-24)*24) -> 1 | BC37: =IF(BB37>=0,BB37,BB37+24) -> 1 | BD37: =IF(AX37<=0,AN37,IF(AX37>=0.1,AX37/24)) -> 0.041666667
A38: P. RETRIBUIDO | C38: 0 | R38: =CONTROL!F41 -> G | S38: =CONTROL!G41 -> 0.29166667 | U38: A | V38: =CONTROL!H41 -> 0.33333333 | AK38: =AH115 -> 96 | AL38: V7 | AN38: =IF(AS38/24=0,0,AS38/24) -> 0 | AO38: =IF(BA38=0,"",BA38) -> 0.041666667 | AP38: =S38*24 -> 7 | AQ38: =V38*24 -> 8 | AR38: =AS38 -> 0 | AS38: =IF(AV38>=4,AT38,AT38) -> 0 | AT38: =IF(AV38>8,8,AU38) -> 0 | AU38: =IF(AV38<0,0,AV38) -> 0 | AV38: =IF(AP38=AQ38,0,IF(AP38>AQ38,AW38,IF(AP38>=6,AX38,AQ38-AP38))) -> -1 | AW38: =IF(AP38<6,(AQ38-22+24)+(6-AP38),IF(AP38>=22,AY38,IF(AV8<=6,(AQ38-22)+24,8))) -> 10 | AX38: =IF(AQ38>22,AZ38,IF(AP38<AQ38,AP38-AQ38,IF(AP38>6,0,(6-AP38)))) -> -1 | AY38: =IF(AQ38<=6,(AQ38-AP38)+24,IF(AQ38>22,8,(6-AP38)+24)) -> 23 | AZ38: =IF(AP38<=6,(6-AP38)+(AQ38-22),IF(AP38>22,(AQ38-AP38),(AQ38-22))) -> -14 | BA38: =IF(V38-S38>=0,V38-S38,V38-S38+24) -> 0.041666667 | BB38: =IF(AO38<1,AO38*24,(AO38-24)*24) -> 1 | BC38: =IF(BB38>=0,BB38,BB38+24) -> 1 | BD38: =IF(AX38<=0,AN38,IF(AX38>=0.1,AX38/24)) -> 0
R39: =CONTROL!F42 -> H | S39: =CONTROL!G42 -> 0.33333333 | U39: A | V39: =CONTROL!H42 -> 0.375 | AK39: =AH126 -> 72 | AL39: V8 | AN39: =IF(AS39/24=0,0,AS39/24) -> 0 | AO39: =IF(BA39=0,"",BA39) -> 0.041666667 | AP39: =S39*24 -> 8 | AQ39: =V39*24 -> 9 | AR39: =AS39 -> 0 | AS39: =IF(AV39>=4,AT39,AT39) -> 0 | AT39: =IF(AV39>8,8,AU39) -> 0 | AU39: =IF(AV39<0,0,AV39) -> 0 | AV39: =IF(AP39=AQ39,0,IF(AP39>AQ39,AW39,IF(AP39>=6,AX39,AQ39-AP39))) -> -1 | AW39: =IF(AP39<6,(AQ39-22+24)+(6-AP39),IF(AP39>=22,AY39,IF(AV9<=6,(AQ39-22)+24,8))) -> 11 | AX39: =IF(AQ39>22,AZ39,IF(AP39<AQ39,AP39-AQ39,IF(AP39>6,0,(6-AP39)))) -> -1 | AY39: =IF(AQ39<=6,(AQ39-AP39)+24,IF(AQ39>22,8,(6-AP39)+24)) -> 22 | AZ39: =IF(AP39<=6,(6-AP39)+(AQ39-22),IF(AP39>22,(AQ39-AP39),(AQ39-22))) -> -13 | BA39: =IF(V39-S39>=0,V39-S39,V39-S39+24) -> 0.041666667 | BB39: =IF(AO39<1,AO39*24,(AO39-24)*24) -> 1 | BC39: =IF(BB39>=0,BB39,BB39+24) -> 1 | BD39: =IF(AX39<=0,AN39,IF(AX39>=0.1,AX39/24)) -> 0
R40: =CONTROL!F43 -> I | S40: =CONTROL!G43 -> 0.41666667 | U40: A | V40: =CONTROL!H43 -> 0.45833333 | AK40: =AH137 -> 136 | AL40: V9 | AN40: =IF(AS40/24=0,0,AS40/24) -> 0 | AO40: =IF(BA40=0,"",BA40) -> 0.041666667 | AP40: =S40*24+24 -> 34 | AQ40: =V40*24 -> 11 | AR40: =AS40 -> 0 | AS40: =IF(AV40>=4,AT40,AT40) -> 0 | AT40: =IF(AV40>8,8,AU40) -> 0 | AU40: =IF(AV40<0,0,AV40) -> 0 | AV40: =IF(AP40=AQ40,0,IF(AP40>AQ40,AW40,IF(AP40>=6,AX40,AQ40-AP40))) -> -4 | AW40: =IF(AP40<6,(AQ40-22+24)+(6-AP40),IF(AP40>=22,AY40,IF(AV10<=6,(AQ40-22)+24,8))) -> -4 | AX40: =IF(AQ40>22,AZ40,IF(AP40<AQ40,AP40-AQ40,IF(AP40>6,0,(6-AP40)))) -> 0 | AY40: =IF(AQ40<=6,(AQ40-AP40)+24,IF(AQ40>22,8,(6-AP40)+24)) -> -4 | AZ40: =IF(AP40<=6,(6-AP40)+(AQ40-22),IF(AP40>22,(AQ40-AP40),(AQ40-22))) -> -23 | BA40: =IF(V40-S40>=0,V40-S40,V40-S40+24) -> 0.041666667 | BB40: =IF(AO40<1,AO40*24,(AO40-24)*24) -> 1 | BC40: =IF(BB40>=0,BB40,BB40+24) -> 1 | BD40: =IF(AX40<=0,AN40,IF(AX40>=0.1,AX40/24)) -> 0
AK41: =AH148 -> 0 | AL41: V10 | AP41: =S41*24 -> 0 | AR41: 1 | AS41: 2 | AT41: 3 | AU41: 4 | AV41: 5 | AW41: 6 | AX41: 7 | AY41: 8 | AZ41: 9
C42: http://oscar.org.es | W42: =CONTROL!B38 -> OSCAR ORGEIRA © 20.03.00 EXCEL | AK42: =AH159 -> 0 | AL42: V11
C43: notas | E43: *Aquí notas que se vean en el cuadrante... | AK43: =AH170 -> 0 | AL43: V12
BE44: =INDEX({"do";"lu";"ma";"mi";"ju";"vi";"sa"},1+MOD($AR$47+4-2,7)) -> ju
B45: FEST. FINDE | C45: =IF(C7="S",IF(C7="",0,1),IF(C7="D",IF(C7="",0,1),"")) -> 1 | D45: =IF(D7="S",IF(D7="",0,1),IF(D7="D",IF(D7="",0,1),"")) | E45: =IF(E7="S",IF(E7="",0,1),IF(E7="D",IF(E7="",0,1),"")) | F45: =IF(F7="S",IF(F7="",0,1),IF(F7="D",IF(F7="",0,1),"")) | G45: =IF(G7="S",IF(G7="",0,1),IF(G7="D",IF(G7="",0,1),"")) | H45: =IF(H7="S",IF(H7="",0,1),IF(H7="D",IF(H7="",0,1),"")) | I45: =IF(I7="S",IF(I7="",0,1),IF(I7="D",IF(I7="",0,1),"")) -> 1 | J45: =IF(J7="S",IF(J7="",0,1),IF(J7="D",IF(J7="",0,1),"")) -> 1 | ... AH45: =IF(AH7="S",IF(AH7="",0,1),IF(AH7="D",IF(AH7="",0,1),"")) | AI45: SUMAS | BE45: =IF(MONTH($Q$4)<>MONTH($Q$4-(WEEKDAY($Q$4,1)-($AR$47-1))-IF((WEEKDAY($Q$4,1)-($AR$47-1))<=0,7,0)+(ROW(BE45)-ROW($AN$51))*7+(COLUMN(BE45)-COLUMN($AN$51)+1)),"",$Q$4-(WEEKDAY($Q$4,1)-($AR$47-1))-IF((WEEKDAY($Q$4,1)-($AR$47-1))<=0,7,0)+(ROW(BE45)-ROW($AN$51))*7+(COLUMN(BE45)-COLUMN($AN$51)+1))
...

Sheet ABRIL
B3: =C32 -> EMPRESA
B4: =C33 -> CENTRO | Q4: =DATE($C$34,$C$35,1) -> 46113 | Z4: =SUM(AH51+AH62+AH73+AH84+AH95+AH106+AH117+AH128+AH139+AH150+AH161+AH172) -> 1680 | AC4: h. centro
AE5: =IF(CA59=28,IF(CA59="",0,1),IF(CA59=1,IF(CA59="",0,1),"")) | AF5: =IF(CA59=29,IF(CA59="",0,1),IF(CA59=1,IF(CA59="",0,1),"")) | AG5: =IF(CA59=30,IF(CA59="",0,1),IF(CA59=1,IF(CA59="",0,1),"")) -> 1 | AH5: =IF(CA59=31,IF(CA59="",0,1),IF(CA59=1,IF(CA59="",0,1),""))
B6: FESTIVO
B7: DIA SEM. | C7: =IF(AV47="LUNES","lu",IF(AV47="MARTES","ma",IF(AV47="MIERCOLES","mi",IF(AV47="JUEVES","ju",IF(AV47="VIERNES","vi",IF(AV47="SABADO","S",IF(AV47="DOMINGO","D",""))))))) -> mi | D7: =IF(C7="lu","ma",IF(C7="ma","mi",IF(C7="mi","ju",IF(C7="ju","vi",IF(C7="vi","S",IF(C7="S","D",IF(C7="D","lu",""))))))) -> ju | E7: =IF(D7="lu","ma",IF(D7="ma","mi",IF(D7="mi","ju",IF(D7="ju","vi",IF(D7="vi","S",IF(D7="S","D",IF(D7="D","lu",""))))))) -> vi | F7: =IF(E7="lu","ma",IF(E7="ma","mi",IF(E7="mi","ju",IF(E7="ju","vi",IF(E7="vi","S",IF(E7="S","D",IF(E7="D","lu",""))))))) -> S | G7: =IF(F7="lu","ma",IF(F7="ma","mi",IF(F7="mi","ju",IF(F7="ju","vi",IF(F7="vi","S",IF(F7="S","D",IF(F7="D","lu",""))))))) -> D | H7: =IF(G7="lu","ma",IF(G7="ma","mi",IF(G7="mi","ju",IF(G7="ju","vi",IF(G7="vi","S",IF(G7="S","D",IF(G7="D","lu",""))))))) -> lu | I7: =IF(H7="lu","ma",IF(H7="ma","mi",IF(H7="mi","ju",IF(H7="ju","vi",IF(H7="vi","S",IF(H7="S","D",IF(H7="D","lu",""))))))) -> ma | J7: =IF(I7="lu","ma",IF(I7="ma","mi",IF(I7="mi","ju",IF(I7="ju","vi",IF(I7="vi","S",IF(I7="S","D",IF(I7="D","lu",""))))))) -> mi | K7: =IF(J7="lu","ma",IF(J7="ma","mi",IF(J7="mi","ju",IF(J7="ju","vi",IF(J7="vi","S",IF(J7="S","D",IF(J7="D","lu",""))))))) -> ju | ... AD7: =IF(AC7="lu","ma",IF(AC7="ma","mi",IF(AC7="mi","ju",IF(AC7="ju","vi",IF(AC7="vi","S",IF(AC7="S","D",IF(AC7="D","lu",""))))))) -> ma | AE7: =IF(AE8="","",IF(AD7="lu","ma",IF(AD7="ma","mi",IF(AD7="mi","ju",IF(AD7="ju","vi",IF(AD7="vi","S",IF(AD7="S","D",IF(AD7="D","lu","")))))))) -> mi | AF7: =IF(AF8="","",IF(AE7="lu","ma",IF(AE7="ma","mi",IF(AE7="mi","ju",IF(AE7="ju","vi",IF(AE7="vi","S",IF(AE7="S","D",IF(AE7="D","lu","")))))))) -> ju | AG7: =IF(AG8="","",IF(AF7="lu","ma",IF(AF7="ma","mi",IF(AF7="mi","ju",IF(AF7="ju","vi",IF(AF7="vi","S",IF(AF7="S","D",IF(AF7="D","lu",""))))))))
A8: VIGILANTE Nº | C8: 1 | D8: 2 | E8: 3 | F8: 4 | G8: 5 | H8: 6 | I8: 7 | J8: 8 | K8: 9 | L8: 10 | M8: 11 | N8: 12 | O8: 13 | P8: 14 | Q8: 15 | R8: 16 | S8: 17 | T8: 18 | U8: 19 | V8: 20 | W8: 21 | X8: 22 | Y8: 23 | Z8: 24 | AA8: 25 | AB8: 26 | AC8: 27 | AD8: 28 | AE8: =IF(CA59=28,"",IF(CA59=29,29,IF(CA59=30,29,IF(CA59=31,29,"")))) -> 29 | AF8: =IF(CA59=28,"",IF(CA59=29,"",IF(CA59=30,30,IF(CA59=31,30,"")))) -> 30 | AG8: =IF(CA59=28,"",IF(CA59=29,"",IF(CA59=30,"",IF(CA59=31,31,"")))) | AH8: HORAS | AI8: EXT | AJ8: FES | AK8: NOC | AL8: DV
A9: JAVI | C9: D2 | E9: D2 | F9: D2 | G9: D2 | I9: D1 | J9: D2 | K9: D2 | O9: N2 | P9: N2 | R9: N3 | S9: N2 | T9: N2 | U9: N2 | X9: N2 | Y9: N2 | Z9: N3 | AC9: N2 | AD9: N2 | AH9: =SUM(AH50:AH51) -> 208 | AI9: =AH9-C37 -> 46 | AJ9: =SUM(C55:AG55) -> 54 | AK9: =AK32 -> 88 | AL9: =SUM(C56:AG56) -> 0 | CB9: =ROUNDDOWN(AH9,0) -> 208 | CC9: =AH9-INT(AH9) -> 0 | CD9: =CC9/24 -> 0
A10: PAREDES | C10: N2 | D10: N2 | H10: N2 | I10: N2 | L10: N2 | M10: N2 | N10: N2 | Q10: N2 | R10: N2 | V10: N2 | W10: N2 | Z10: N2 | AA10: N2 | AB10: N2 | AE10: N2 | AF10: N2 | AH10: =SUM(AH61:AH62) -> 192 | AI10: =AH10-C37 -> 30 | AJ10: =SUM(C66:AG66) -> 48 | AK10: =AK33 -> 128 | AL10: =SUM(C67:AG67) -> 0
A11: JUAN | C11: B | D11: B | E11: B | F11: B | G11: B | H11: B | I11: B | J11: B | K11: B | L11: B | M11: B | N11: B | O11: B | P11: B | Q11: B | R11: B | S11: B | T11: B | U11: B | V11: B | W11: B | X11: B | Y11: B | Z11: B | AA11: B | AB11: B | AC11: B | AD11: B | AE11: B | AF11: B | AH11: =SUM(AH72:AH73) -> 0 | AI11: =AH11-C37 -> -162 | AJ11: =SUM(C77:AG77) -> 0 | AK11: =AK34 -> 0 | AL11: =SUM(C78:AG78) -> 0
A12: MILOU | D12: D2 | H12: D2 | I12: D2 | J12: N1 | L12: D2 | M12: D2 | N12: D2 | O12: D2 | P12: D2 | Q12: D2 | R12: D2 | V12: D2 | W12: D2 | Z12: D2 | AA12: D2 | AB12: D2 | AE12: D2 | AF12: D2 | AH12: =SUM(AH83:AH84) -> 216 | AI12: =AH12-C37 -> 54 | AJ12: =SUM(C88:AG88) -> 48 | AK12: =AK35 -> 8 | AL12: =SUM(C89:AG89) -> 0
